<?xml version="1.0" ?>
<!-- =================================================================================== -->
<!-- |    This document was autogenerated by xacro from gripper_robot.xacro            | -->
<!-- |    EDITING THIS FILE BY HAND IS NOT RECOMMENDED                                 | -->
<!-- =================================================================================== -->
<robot name="gripper_robot">
  <!-- 12mm disc thickness -->
  <!-- ~62% of disc radius = 22mm from center (between 25% and 100%) -->
  <!-- Base Link -->
  <link name="base_link">
    <visual>
      <origin rpy="0 0 0" xyz="0 0 0.04"/>
      <geometry>
        <box size="0.2 0.2 0.08"/>
      </geometry>
      <material name="brown">
        <color rgba="0.6 0.4 0.2 1.0"/>
      </material>
    </visual>
    <collision>
      <origin rpy="0 0 0" xyz="0 0 0.04"/>
      <geometry>
        <box size="0.2 0.2 0.08"/>
      </geometry>
    </collision>
    <inertial>
      <origin rpy="0 0 0" xyz="0 0 0.04"/>
      <mass value="2.0"/>
      <inertia ixx="0.01" ixy="0" ixz="0" iyy="0.01" iyz="0" izz="0.01"/>
    </inertial>
  </link>
  <joint name="base_to_seg1" type="fixed">
    <parent link="base_link"/>
    <child link="seg1_mount"/>
    <origin rpy="0 0 0" xyz="0 0 0.08"/>
  </joint>
  <link name="seg1_mount">
    <inertial>
      <mass value="0.01"/>
      <inertia ixx="0.00001" ixy="0" ixz="0" iyy="0.00001" iyz="0" izz="0.00001"/>
    </inertial>
  </link>
  <!-- Revolute Joint X (Roll) -->
  <joint name="seg1_joint_x" type="revolute">
    <parent link="seg1_mount"/>
    <child link="seg1_x_link"/>
    <origin rpy="0 0 0" xyz="0 0 0"/>
    <axis xyz="1 0 0"/>
    <limit effort="100" lower="-0.2094" upper="0.2094" velocity="1.0"/>
    <dynamics damping="0.7" friction="0.0"/>
  </joint>
  <link name="seg1_x_link">
    <inertial>
      <origin rpy="0 0 0" xyz="0 0 0"/>
      <mass value="0.01"/>
      <inertia ixx="0.00001" ixy="0" ixz="0" iyy="0.00001" iyz="0" izz="0.00001"/>
    </inertial>
  </link>
  <!-- Revolute Joint Y (Pitch) -->
  <joint name="seg1_joint_y" type="revolute">
    <parent link="seg1_x_link"/>
    <child link="seg1_y_link"/>
    <origin rpy="0 0 0" xyz="0 0 0"/>
    <axis xyz="0 1 0"/>
    <limit effort="100" lower="-0.2094" upper="0.2094" velocity="1.0"/>
    <dynamics damping="0.7" friction="0.0"/>
  </joint>
  <link name="seg1_y_link">
    <inertial>
      <origin rpy="0 0 0" xyz="0 0 0"/>
      <mass value="0.01"/>
      <inertia ixx="0.00001" ixy="0" ixz="0" iyy="0.00001" iyz="0" izz="0.00001"/>
    </inertial>
  </link>
  <!-- Fixed H distance joint -->
  <joint name="seg1_fixed_h" type="fixed">
    <parent link="seg1_y_link"/>
    <child link="seg1_mid_link"/>
    <origin rpy="0 0 0" xyz="0 0 0.022"/>
  </joint>
  <!-- Middle link with disc platform -->
  <link name="seg1_mid_link">
    <visual>
      <origin rpy="0 0 0" xyz="0 0 0"/>
      <geometry>
        <cylinder length="0.012" radius="0.0352"/>
      </geometry>
      <material name="disc_1">
        <color rgba="1.0 0.6 0.2 1.0"/>
      </material>
    </visual>
    <collision>
      <origin rpy="0 0 0" xyz="0 0 0"/>
      <geometry>
        <cylinder length="0.012" radius="0.0352"/>
      </geometry>
    </collision>
    <inertial>
      <origin rpy="0 0 0" xyz="0 0 0"/>
      <mass value="0.5"/>
      <inertia ixx="0.002" ixy="0" ixz="0" iyy="0.002" iyz="0" izz="0.003"/>
    </inertial>
  </link>
  <!-- Revolute Joint X (Roll) -->
  <joint name="seg2_joint_x" type="revolute">
    <parent link="seg1_mid_link"/>
    <child link="seg2_x_link"/>
    <origin rpy="0 0 0" xyz="0 0 0"/>
    <axis xyz="1 0 0"/>
    <limit effort="100" lower="-0.2094" upper="0.2094" velocity="1.0"/>
    <mimic joint="seg1_joint_x" multiplier="1.0" offset="0.0"/>
    <dynamics damping="0.1" friction="0.0"/>
  </joint>
  <link name="seg2_x_link">
    <inertial>
      <origin rpy="0 0 0" xyz="0 0 0"/>
      <mass value="0.01"/>
      <inertia ixx="0.00001" ixy="0" ixz="0" iyy="0.00001" iyz="0" izz="0.00001"/>
    </inertial>
  </link>
  <!-- Revolute Joint Y (Pitch) -->
  <joint name="seg2_joint_y" type="revolute">
    <parent link="seg2_x_link"/>
    <child link="seg2_y_link"/>
    <origin rpy="0 0 0" xyz="0 0 0"/>
    <axis xyz="0 1 0"/>
    <limit effort="100" lower="-0.2094" upper="0.2094" velocity="1.0"/>
    <mimic joint="seg1_joint_y" multiplier="1.0" offset="0.0"/>
    <dynamics damping="0.1" friction="0.0"/>
  </joint>
  <link name="seg2_y_link">
    <inertial>
      <origin rpy="0 0 0" xyz="0 0 0"/>
      <mass value="0.01"/>
      <inertia ixx="0.00001" ixy="0" ixz="0" iyy="0.00001" iyz="0" izz="0.00001"/>
    </inertial>
  </link>
  <!-- Fixed H distance joint -->
  <joint name="seg2_fixed_h" type="fixed">
    <parent link="seg2_y_link"/>
    <child link="seg2_mid_link"/>
    <origin rpy="0 0 0" xyz="0 0 0.022"/>
  </joint>
  <!-- Middle link with disc platform -->
  <link name="seg2_mid_link">
    <visual>
      <origin rpy="0 0 0" xyz="0 0 0"/>
      <geometry>
        <cylinder length="0.012" radius="0.0352"/>
      </geometry>
      <material name="disc_2">
        <color rgba="1.0 0.6 0.2 1.0"/>
      </material>
    </visual>
    <collision>
      <origin rpy="0 0 0" xyz="0 0 0"/>
      <geometry>
        <cylinder length="0.012" radius="0.0352"/>
      </geometry>
    </collision>
    <inertial>
      <origin rpy="0 0 0" xyz="0 0 0"/>
      <mass value="0.5"/>
      <inertia ixx="0.002" ixy="0" ixz="0" iyy="0.002" iyz="0" izz="0.003"/>
    </inertial>
  </link>
  <!-- Revolute Joint X (Roll) -->
  <joint name="seg3_joint_x" type="revolute">
    <parent link="seg2_mid_link"/>
    <child link="seg3_x_link"/>
    <origin rpy="0 0 0" xyz="0 0 0"/>
    <axis xyz="1 0 0"/>
    <limit effort="100" lower="-0.2094" upper="0.2094" velocity="1.0"/>
    <mimic joint="seg1_joint_x" multiplier="1.0" offset="0.0"/>
    <dynamics damping="0.1" friction="0.0"/>
  </joint>
  <link name="seg3_x_link">
    <inertial>
      <origin rpy="0 0 0" xyz="0 0 0"/>
      <mass value="0.01"/>
      <inertia ixx="0.00001" ixy="0" ixz="0" iyy="0.00001" iyz="0" izz="0.00001"/>
    </inertial>
  </link>
  <!-- Revolute Joint Y (Pitch) -->
  <joint name="seg3_joint_y" type="revolute">
    <parent link="seg3_x_link"/>
    <child link="seg3_y_link"/>
    <origin rpy="0 0 0" xyz="0 0 0"/>
    <axis xyz="0 1 0"/>
    <limit effort="100" lower="-0.2094" upper="0.2094" velocity="1.0"/>
    <mimic joint="seg1_joint_y" multiplier="1.0" offset="0.0"/>
    <dynamics damping="0.1" friction="0.0"/>
  </joint>
  <link name="seg3_y_link">
    <inertial>
      <origin rpy="0 0 0" xyz="0 0 0"/>
      <mass value="0.01"/>
      <inertia ixx="0.00001" ixy="0" ixz="0" iyy="0.00001" iyz="0" izz="0.00001"/>
    </inertial>
  </link>
  <!-- Fixed H distance joint -->
  <joint name="seg3_fixed_h" type="fixed">
    <parent link="seg3_y_link"/>
    <child link="seg3_mid_link"/>
    <origin rpy="0 0 0" xyz="0 0 0.022"/>
  </joint>
  <!-- Middle link with disc platform -->
  <link name="seg3_mid_link">
    <visual>
      <origin rpy="0 0 0" xyz="0 0 0"/>
      <geometry>
        <cylinder length="0.012" radius="0.0352"/>
      </geometry>
      <material name="disc_3">
        <color rgba="1.0 0.6 0.2 1.0"/>
      </material>
    </visual>
    <collision>
      <origin rpy="0 0 0" xyz="0 0 0"/>
      <geometry>
        <cylinder length="0.012" radius="0.0352"/>
      </geometry>
    </collision>
    <inertial>
      <origin rpy="0 0 0" xyz="0 0 0"/>
      <mass value="0.5"/>
      <inertia ixx="0.002" ixy="0" ixz="0" iyy="0.002" iyz="0" izz="0.003"/>
    </inertial>
  </link>
  <!-- Revolute Joint X (Roll) -->
  <joint name="seg4_joint_x" type="revolute">
    <parent link="seg3_mid_link"/>
    <child link="seg4_x_link"/>
    <origin rpy="0 0 0" xyz="0 0 0"/>
    <axis xyz="1 0 0"/>
    <limit effort="100" lower="-0.2094" upper="0.2094" velocity="1.0"/>
    <mimic joint="seg1_joint_x" multiplier="1.0" offset="0.0"/>
    <dynamics damping="0.1" friction="0.0"/>
  </joint>
  <link name="seg4_x_link">
    <inertial>
      <origin rpy="0 0 0" xyz="0 0 0"/>
      <mass value="0.01"/>
      <inertia ixx="0.00001" ixy="0" ixz="0" iyy="0.00001" iyz="0" izz="0.00001"/>
    </inertial>
  </link>
  <!-- Revolute Joint Y (Pitch) -->
  <joint name="seg4_joint_y" type="revolute">
    <parent link="seg4_x_link"/>
    <child link="seg4_y_link"/>
    <origin rpy="0 0 0" xyz="0 0 0"/>
    <axis xyz="0 1 0"/>
    <limit effort="100" lower="-0.2094" upper="0.2094" velocity="1.0"/>
    <mimic joint="seg1_joint_y" multiplier="1.0" offset="0.0"/>
    <dynamics damping="0.1" friction="0.0"/>
  </joint>
  <link name="seg4_y_link">
    <inertial>
      <origin rpy="0 0 0" xyz="0 0 0"/>
      <mass value="0.01"/>
      <inertia ixx="0.00001" ixy="0" ixz="0" iyy="0.00001" iyz="0" izz="0.00001"/>
    </inertial>
  </link>
  <!-- Fixed H distance joint -->
  <joint name="seg4_fixed_h" type="fixed">
    <parent link="seg4_y_link"/>
    <child link="seg4_mid_link"/>
    <origin rpy="0 0 0" xyz="0 0 0.022"/>
  </joint>
  <!-- Middle link with disc platform -->
  <link name="seg4_mid_link">
    <visual>
      <origin rpy="0 0 0" xyz="0 0 0"/>
      <geometry>
        <cylinder length="0.012" radius="0.0352"/>
      </geometry>
      <material name="disc_4">
        <color rgba="1.0 0.6 0.2 1.0"/>
      </material>
    </visual>
    <collision>
      <origin rpy="0 0 0" xyz="0 0 0"/>
      <geometry>
        <cylinder length="0.012" radius="0.0352"/>
      </geometry>
    </collision>
    <inertial>
      <origin rpy="0 0 0" xyz="0 0 0"/>
      <mass value="0.5"/>
      <inertia ixx="0.002" ixy="0" ixz="0" iyy="0.002" iyz="0" izz="0.003"/>
    </inertial>
  </link>
  <!-- Revolute Joint X (Roll) -->
  <joint name="seg5_joint_x" type="revolute">
    <parent link="seg4_mid_link"/>
    <child link="seg5_x_link"/>
    <origin rpy="0 0 0" xyz="0 0 0"/>
    <axis xyz="1 0 0"/>
    <limit effort="100" lower="-0.2094" upper="0.2094" velocity="1.0"/>
    <mimic joint="seg1_joint_x" multiplier="1.0" offset="0.0"/>
    <dynamics damping="0.1" friction="0.0"/>
  </joint>
  <link name="seg5_x_link">
    <inertial>
      <origin rpy="0 0 0" xyz="0 0 0"/>
      <mass value="0.01"/>
      <inertia ixx="0.00001" ixy="0" ixz="0" iyy="0.00001" iyz="0" izz="0.00001"/>
    </inertial>
  </link>
  <!-- Revolute Joint Y (Pitch) -->
  <joint name="seg5_joint_y" type="revolute">
    <parent link="seg5_x_link"/>
    <child link="seg5_y_link"/>
    <origin rpy="0 0 0" xyz="0 0 0"/>
    <axis xyz="0 1 0"/>
    <limit effort="100" lower="-0.2094" upper="0.2094" velocity="1.0"/>
    <mimic joint="seg1_joint_y" multiplier="1.0" offset="0.0"/>
    <dynamics damping="0.1" friction="0.0"/>
  </joint>
  <link name="seg5_y_link">
    <inertial>
      <origin rpy="0 0 0" xyz="0 0 0"/>
      <mass value="0.01"/>
      <inertia ixx="0.00001" ixy="0" ixz="0" iyy="0.00001" iyz="0" izz="0.00001"/>
    </inertial>
  </link>
  <!-- Fixed H distance joint -->
  <joint name="seg5_fixed_h" type="fixed">
    <parent link="seg5_y_link"/>
    <child link="seg5_mid_link"/>
    <origin rpy="0 0 0" xyz="0 0 0.022"/>
  </joint>
  <!-- Middle link with disc platform -->
  <link name="seg5_mid_link">
    <visual>
      <origin rpy="0 0 0" xyz="0 0 0"/>
      <geometry>
        <cylinder length="0.012" radius="0.0352"/>
      </geometry>
      <material name="disc_5">
        <color rgba="1.0 0.6 0.2 1.0"/>
      </material>
    </visual>
    <collision>
      <origin rpy="0 0 0" xyz="0 0 0"/>
      <geometry>
        <cylinder length="0.012" radius="0.0352"/>
      </geometry>
    </collision>
    <inertial>
      <origin rpy="0 0 0" xyz="0 0 0"/>
      <mass value="0.5"/>
      <inertia ixx="0.002" ixy="0" ixz="0" iyy="0.002" iyz="0" izz="0.003"/>
    </inertial>
  </link>
  <!-- Revolute Joint X (Roll) -->
  <joint name="seg6_joint_x" type="revolute">
    <parent link="seg5_mid_link"/>
    <child link="seg6_x_link"/>
    <origin rpy="0 0 0" xyz="0 0 0"/>
    <axis xyz="1 0 0"/>
    <limit effort="100" lower="-0.2094" upper="0.2094" velocity="1.0"/>
    <mimic joint="seg1_joint_x" multiplier="1.0" offset="0.0"/>
    <dynamics damping="0.1" friction="0.0"/>
  </joint>
  <link name="seg6_x_link">
    <inertial>
      <origin rpy="0 0 0" xyz="0 0 0"/>
      <mass value="0.01"/>
      <inertia ixx="0.00001" ixy="0" ixz="0" iyy="0.00001" iyz="0" izz="0.00001"/>
    </inertial>
  </link>
  <!-- Revolute Joint Y (Pitch) -->
  <joint name="seg6_joint_y" type="revolute">
    <parent link="seg6_x_link"/>
    <child link="seg6_y_link"/>
    <origin rpy="0 0 0" xyz="0 0 0"/>
    <axis xyz="0 1 0"/>
    <limit effort="100" lower="-0.2094" upper="0.2094" velocity="1.0"/>
    <mimic joint="seg1_joint_y" multiplier="1.0" offset="0.0"/>
    <dynamics damping="0.1" friction="0.0"/>
  </joint>
  <link name="seg6_y_link">
    <inertial>
      <origin rpy="0 0 0" xyz="0 0 0"/>
      <mass value="0.01"/>
      <inertia ixx="0.00001" ixy="0" ixz="0" iyy="0.00001" iyz="0" izz="0.00001"/>
    </inertial>
  </link>
  <!-- Fixed H distance joint -->
  <joint name="seg6_fixed_h" type="fixed">
    <parent link="seg6_y_link"/>
    <child link="seg6_mid_link"/>
    <origin rpy="0 0 0" xyz="0 0 0.022"/>
  </joint>
  <!-- Middle link with disc platform -->
  <link name="seg6_mid_link">
    <visual>
      <origin rpy="0 0 0" xyz="0 0 0"/>
      <geometry>
        <cylinder length="0.012" radius="0.0352"/>
      </geometry>
      <material name="disc_6">
        <color rgba="1.0 0.6 0.2 1.0"/>
      </material>
    </visual>
    <collision>
      <origin rpy="0 0 0" xyz="0 0 0"/>
      <geometry>
        <cylinder length="0.012" radius="0.0352"/>
      </geometry>
    </collision>
    <inertial>
      <origin rpy="0 0 0" xyz="0 0 0"/>
      <mass value="0.5"/>
      <inertia ixx="0.002" ixy="0" ixz="0" iyy="0.002" iyz="0" izz="0.003"/>
    </inertial>
  </link>
  <!-- Revolute Joint X (Roll) -->
  <joint name="seg7_joint_x" type="revolute">
    <parent link="seg6_mid_link"/>
    <child link="seg7_x_link"/>
    <origin rpy="0 0 0" xyz="0 0 0"/>
    <axis xyz="1 0 0"/>
    <limit effort="100" lower="-0.2094" upper="0.2094" velocity="1.0"/>
    <mimic joint="seg1_joint_x" multiplier="1.0" offset="0.0"/>
    <dynamics damping="0.1" friction="0.0"/>
  </joint>
  <link name="seg7_x_link">
    <inertial>
      <origin rpy="0 0 0" xyz="0 0 0"/>
      <mass value="0.01"/>
      <inertia ixx="0.00001" ixy="0" ixz="0" iyy="0.00001" iyz="0" izz="0.00001"/>
    </inertial>
  </link>
  <!-- Revolute Joint Y (Pitch) -->
  <joint name="seg7_joint_y" type="revolute">
    <parent link="seg7_x_link"/>
    <child link="seg7_y_link"/>
    <origin rpy="0 0 0" xyz="0 0 0"/>
    <axis xyz="0 1 0"/>
    <limit effort="100" lower="-0.2094" upper="0.2094" velocity="1.0"/>
    <mimic joint="seg1_joint_y" multiplier="1.0" offset="0.0"/>
    <dynamics damping="0.1" friction="0.0"/>
  </joint>
  <link name="seg7_y_link">
    <inertial>
      <origin rpy="0 0 0" xyz="0 0 0"/>
      <mass value="0.01"/>
      <inertia ixx="0.00001" ixy="0" ixz="0" iyy="0.00001" iyz="0" izz="0.00001"/>
    </inertial>
  </link>
  <!-- Fixed H distance joint -->
  <joint name="seg7_fixed_h" type="fixed">
    <parent link="seg7_y_link"/>
    <child link="seg7_mid_link"/>
    <origin rpy="0 0 0" xyz="0 0 0.022"/>
  </joint>
  <!-- Middle link with disc platform -->
  <link name="seg7_mid_link">
    <visual>
      <origin rpy="0 0 0" xyz="0 0 0"/>
      <geometry>
        <cylinder length="0.012" radius="0.0352"/>
      </geometry>
      <material name="disc_7">
        <color rgba="1.0 0.6 0.2 1.0"/>
      </material>
    </visual>
    <collision>
      <origin rpy="0 0 0" xyz="0 0 0"/>
      <geometry>
        <cylinder length="0.012" radius="0.0352"/>
      </geometry>
    </collision>
    <inertial>
      <origin rpy="0 0 0" xyz="0 0 0"/>
      <mass value="0.5"/>
      <inertia ixx="0.002" ixy="0" ixz="0" iyy="0.002" iyz="0" izz="0.003"/>
    </inertial>
  </link>
  <!-- ===== GRIPPER BASE (on top of seg7) ===== -->
  <joint name="gripper_base_joint" type="fixed">
    <parent link="seg7_mid_link"/>
    <child link="gripper_base"/>
    <origin rpy="0 0 0" xyz="0 0 0.006"/>
  </joint>
  <link name="gripper_base">
    <inertial>
      <mass value="0.1"/>
      <inertia ixx="0.0001" ixy="0" ixz="0" iyy="0.0001" iyz="0" izz="0.0001"/>
    </inertial>
  </link>
  <!-- ===== FINGER 1 (at 0°) ===== -->
  <joint name="finger1_mount" type="fixed">
    <parent link="gripper_base"/>
    <child link="finger1_base"/>
    <origin rpy="0 0 0" xyz="0.022 0 0"/>
  </joint>
  <link name="finger1_base">
    <inertial>
      <mass value="0.01"/>
      <inertia ixx="0.00001" ixy="0" ixz="0" iyy="0.00001" iyz="0" izz="0.00001"/>
    </inertial>
  </link>
  <!-- Revolute Joint (opens/closes) -->
  <joint name="finger1_level1_joint" type="revolute">
    <parent link="finger1_base"/>
    <child link="finger1_level1_link"/>
    <origin rpy="0 0 0" xyz="0 0 0"/>
    <axis xyz="0 1 0"/>
    <limit effort="50" lower="0" upper="0.2094" velocity="1.0"/>
    <dynamics damping="0.5" friction="0.0"/>
  </joint>
  <link name="finger1_level1_link">
    <inertial>
      <origin rpy="0 0 0" xyz="0 0 0"/>
      <mass value="0.01"/>
      <inertia ixx="0.00001" ixy="0" ixz="0" iyy="0.00001" iyz="0" izz="0.00001"/>
    </inertial>
  </link>
  <!-- Fixed H distance to disc -->
  <joint name="finger1_level1_fixed" type="fixed">
    <parent link="finger1_level1_link"/>
    <child link="finger1_level1_disc"/>
    <origin rpy="0 0 0" xyz="0 0 0.022"/>
  </joint>
  <!-- Disc -->
  <link name="finger1_level1_disc">
    <visual>
      <origin rpy="0 0 0" xyz="0 0 0"/>
      <geometry>
        <cylinder length="0.012" radius="0.015"/>
      </geometry>
      <material name="finger1_mat">
        <color rgba="0.2 0.9 0.5 1.0"/>
      </material>
    </visual>
    <collision>
      <origin rpy="0 0 0" xyz="0 0 0"/>
      <geometry>
        <cylinder length="0.012" radius="0.015"/>
      </geometry>
    </collision>
    <inertial>
      <origin rpy="0 0 0" xyz="0 0 0"/>
      <mass value="0.1"/>
      <inertia ixx="0.0001" ixy="0" ixz="0" iyy="0.0001" iyz="0" izz="0.0001"/>
    </inertial>
  </link>
  <!-- Revolute Joint (opens/closes) -->
  <joint name="finger1_level2_joint" type="revolute">
    <parent link="finger1_level1_disc"/>
    <child link="finger1_level2_link"/>
    <origin rpy="0 0 0" xyz="0 0 0"/>
    <axis xyz="0 1 0"/>
    <limit effort="50" lower="0" upper="0.2094" velocity="1.0"/>
    <mimic joint="finger1_level1_joint" multiplier="1.0" offset="0.0"/>
    <dynamics damping="0.1" friction="0.0"/>
  </joint>
  <link name="finger1_level2_link">
    <inertial>
      <origin rpy="0 0 0" xyz="0 0 0"/>
      <mass value="0.01"/>
      <inertia ixx="0.00001" ixy="0" ixz="0" iyy="0.00001" iyz="0" izz="0.00001"/>
    </inertial>
  </link>
  <!-- Fixed H distance to disc -->
  <joint name="finger1_level2_fixed" type="fixed">
    <parent link="finger1_level2_link"/>
    <child link="finger1_level2_disc"/>
    <origin rpy="0 0 0" xyz="0 0 0.022"/>
  </joint>
  <!-- Disc -->
  <link name="finger1_level2_disc">
    <visual>
      <origin rpy="0 0 0" xyz="0 0 0"/>
      <geometry>
        <cylinder length="0.012" radius="0.01375"/>
      </geometry>
      <material name="finger1_mat">
        <color rgba="0.2 0.9 0.5 1.0"/>
      </material>
    </visual>
    <collision>
      <origin rpy="0 0 0" xyz="0 0 0"/>
      <geometry>
        <cylinder length="0.012" radius="0.01375"/>
      </geometry>
    </collision>
    <inertial>
      <origin rpy="0 0 0" xyz="0 0 0"/>
      <mass value="0.1"/>
      <inertia ixx="0.0001" ixy="0" ixz="0" iyy="0.0001" iyz="0" izz="0.0001"/>
    </inertial>
  </link>
  <!-- Revolute Joint (opens/closes) -->
  <joint name="finger1_level3_joint" type="revolute">
    <parent link="finger1_level2_disc"/>
    <child link="finger1_level3_link"/>
    <origin rpy="0 0 0" xyz="0 0 0"/>
    <axis xyz="0 1 0"/>
    <limit effort="50" lower="0" upper="0.2094" velocity="1.0"/>
    <mimic joint="finger1_level1_joint" multiplier="1.0" offset="0.0"/>
    <dynamics damping="0.1" friction="0.0"/>
  </joint>
  <link name="finger1_level3_link">
    <inertial>
      <origin rpy="0 0 0" xyz="0 0 0"/>
      <mass value="0.01"/>
      <inertia ixx="0.00001" ixy="0" ixz="0" iyy="0.00001" iyz="0" izz="0.00001"/>
    </inertial>
  </link>
  <!-- Fixed H distance to disc -->
  <joint name="finger1_level3_fixed" type="fixed">
    <parent link="finger1_level3_link"/>
    <child link="finger1_level3_disc"/>
    <origin rpy="0 0 0" xyz="0 0 0.022"/>
  </joint>
  <!-- Disc -->
  <link name="finger1_level3_disc">
    <visual>
      <origin rpy="0 0 0" xyz="0 0 0"/>
      <geometry>
        <cylinder length="0.012" radius="0.012499999999999999"/>
      </geometry>
      <material name="finger1_mat">
        <color rgba="0.2 0.9 0.5 1.0"/>
      </material>
    </visual>
    <collision>
      <origin rpy="0 0 0" xyz="0 0 0"/>
      <geometry>
        <cylinder length="0.012" radius="0.012499999999999999"/>
      </geometry>
    </collision>
    <inertial>
      <origin rpy="0 0 0" xyz="0 0 0"/>
      <mass value="0.1"/>
      <inertia ixx="0.0001" ixy="0" ixz="0" iyy="0.0001" iyz="0" izz="0.0001"/>
    </inertial>
  </link>
  <!-- Revolute Joint (opens/closes) -->
  <joint name="finger1_level4_joint" type="revolute">
    <parent link="finger1_level3_disc"/>
    <child link="finger1_level4_link"/>
    <origin rpy="0 0 0" xyz="0 0 0"/>
    <axis xyz="0 1 0"/>
    <limit effort="50" lower="0" upper="0.2094" velocity="1.0"/>
    <mimic joint="finger1_level1_joint" multiplier="1.0" offset="0.0"/>
    <dynamics damping="0.1" friction="0.0"/>
  </joint>
  <link name="finger1_level4_link">
    <inertial>
      <origin rpy="0 0 0" xyz="0 0 0"/>
      <mass value="0.01"/>
      <inertia ixx="0.00001" ixy="0" ixz="0" iyy="0.00001" iyz="0" izz="0.00001"/>
    </inertial>
  </link>
  <!-- Fixed H distance to disc -->
  <joint name="finger1_level4_fixed" type="fixed">
    <parent link="finger1_level4_link"/>
    <child link="finger1_level4_disc"/>
    <origin rpy="0 0 0" xyz="0 0 0.022"/>
  </joint>
  <!-- Disc -->
  <link name="finger1_level4_disc">
    <visual>
      <origin rpy="0 0 0" xyz="0 0 0"/>
      <geometry>
        <cylinder length="0.012" radius="0.01125"/>
      </geometry>
      <material name="finger1_mat">
        <color rgba="0.2 0.9 0.5 1.0"/>
      </material>
    </visual>
    <collision>
      <origin rpy="0 0 0" xyz="0 0 0"/>
      <geometry>
        <cylinder length="0.012" radius="0.01125"/>
      </geometry>
    </collision>
    <inertial>
      <origin rpy="0 0 0" xyz="0 0 0"/>
      <mass value="0.1"/>
      <inertia ixx="0.0001" ixy="0" ixz="0" iyy="0.0001" iyz="0" izz="0.0001"/>
    </inertial>
  </link>
  <!-- Revolute Joint (opens/closes) -->
  <joint name="finger1_level5_joint" type="revolute">
    <parent link="finger1_level4_disc"/>
    <child link="finger1_level5_link"/>
    <origin rpy="0 0 0" xyz="0 0 0"/>
    <axis xyz="0 1 0"/>
    <limit effort="50" lower="0" upper="0.2094" velocity="1.0"/>
    <mimic joint="finger1_level1_joint" multiplier="1.0" offset="0.0"/>
    <dynamics damping="0.1" friction="0.0"/>
  </joint>
  <link name="finger1_level5_link">
    <inertial>
      <origin rpy="0 0 0" xyz="0 0 0"/>
      <mass value="0.01"/>
      <inertia ixx="0.00001" ixy="0" ixz="0" iyy="0.00001" iyz="0" izz="0.00001"/>
    </inertial>
  </link>
  <!-- Fixed H distance to disc -->
  <joint name="finger1_level5_fixed" type="fixed">
    <parent link="finger1_level5_link"/>
    <child link="finger1_level5_disc"/>
    <origin rpy="0 0 0" xyz="0 0 0.022"/>
  </joint>
  <!-- Disc -->
  <link name="finger1_level5_disc">
    <visual>
      <origin rpy="0 0 0" xyz="0 0 0"/>
      <geometry>
        <cylinder length="0.012" radius="0.009999999999999998"/>
      </geometry>
      <material name="finger1_mat">
        <color rgba="0.2 0.9 0.5 1.0"/>
      </material>
    </visual>
    <collision>
      <origin rpy="0 0 0" xyz="0 0 0"/>
      <geometry>
        <cylinder length="0.012" radius="0.009999999999999998"/>
      </geometry>
    </collision>
    <inertial>
      <origin rpy="0 0 0" xyz="0 0 0"/>
      <mass value="0.1"/>
      <inertia ixx="0.0001" ixy="0" ixz="0" iyy="0.0001" iyz="0" izz="0.0001"/>
    </inertial>
  </link>
  <!-- Revolute Joint (opens/closes) -->
  <joint name="finger1_level6_joint" type="revolute">
    <parent link="finger1_level5_disc"/>
    <child link="finger1_level6_link"/>
    <origin rpy="0 0 0" xyz="0 0 0"/>
    <axis xyz="0 1 0"/>
    <limit effort="50" lower="0" upper="0.2094" velocity="1.0"/>
    <mimic joint="finger1_level1_joint" multiplier="1.0" offset="0.0"/>
    <dynamics damping="0.1" friction="0.0"/>
  </joint>
  <link name="finger1_level6_link">
    <inertial>
      <origin rpy="0 0 0" xyz="0 0 0"/>
      <mass value="0.01"/>
      <inertia ixx="0.00001" ixy="0" ixz="0" iyy="0.00001" iyz="0" izz="0.00001"/>
    </inertial>
  </link>
  <!-- Fixed H distance to disc -->
  <joint name="finger1_level6_fixed" type="fixed">
    <parent link="finger1_level6_link"/>
    <child link="finger1_level6_disc"/>
    <origin rpy="0 0 0" xyz="0 0 0.022"/>
  </joint>
  <!-- Disc -->
  <link name="finger1_level6_disc">
    <visual>
      <origin rpy="0 0 0" xyz="0 0 0"/>
      <geometry>
        <cylinder length="0.012" radius="0.00875"/>
      </geometry>
      <material name="finger1_mat">
        <color rgba="0.2 0.9 0.5 1.0"/>
      </material>
    </visual>
    <collision>
      <origin rpy="0 0 0" xyz="0 0 0"/>
      <geometry>
        <cylinder length="0.012" radius="0.00875"/>
      </geometry>
    </collision>
    <inertial>
      <origin rpy="0 0 0" xyz="0 0 0"/>
      <mass value="0.1"/>
      <inertia ixx="0.0001" ixy="0" ixz="0" iyy="0.0001" iyz="0" izz="0.0001"/>
    </inertial>
  </link>
  <!-- Revolute Joint (opens/closes) -->
  <joint name="finger1_level7_joint" type="revolute">
    <parent link="finger1_level6_disc"/>
    <child link="finger1_level7_link"/>
    <origin rpy="0 0 0" xyz="0 0 0"/>
    <axis xyz="0 1 0"/>
    <limit effort="50" lower="0" upper="0.2094" velocity="1.0"/>
    <mimic joint="finger1_level1_joint" multiplier="1.0" offset="0.0"/>
    <dynamics damping="0.1" friction="0.0"/>
  </joint>
  <link name="finger1_level7_link">
    <inertial>
      <origin rpy="0 0 0" xyz="0 0 0"/>
      <mass value="0.01"/>
      <inertia ixx="0.00001" ixy="0" ixz="0" iyy="0.00001" iyz="0" izz="0.00001"/>
    </inertial>
  </link>
  <!-- Fixed H distance to disc -->
  <joint name="finger1_level7_fixed" type="fixed">
    <parent link="finger1_level7_link"/>
    <child link="finger1_level7_disc"/>
    <origin rpy="0 0 0" xyz="0 0 0.022"/>
  </joint>
  <!-- Disc -->
  <link name="finger1_level7_disc">
    <visual>
      <origin rpy="0 0 0" xyz="0 0 0"/>
      <geometry>
        <cylinder length="0.012" radius="0.0075"/>
      </geometry>
      <material name="finger1_mat">
        <color rgba="0.2 0.9 0.5 1.0"/>
      </material>
    </visual>
    <collision>
      <origin rpy="0 0 0" xyz="0 0 0"/>
      <geometry>
        <cylinder length="0.012" radius="0.0075"/>
      </geometry>
    </collision>
    <inertial>
      <origin rpy="0 0 0" xyz="0 0 0"/>
      <mass value="0.1"/>
      <inertia ixx="0.0001" ixy="0" ixz="0" iyy="0.0001" iyz="0" izz="0.0001"/>
    </inertial>
  </link>
  <!-- ===== FINGER 2 (at 120°) ===== -->
  <joint name="finger2_mount" type="fixed">
    <parent link="gripper_base"/>
    <child link="finger2_base"/>
    <origin rpy="0 0 2.0944" xyz="-0.0110000933118101 0.0190525050093543 0"/>
  </joint>
  <link name="finger2_base">
    <inertial>
      <mass value="0.01"/>
      <inertia ixx="0.00001" ixy="0" ixz="0" iyy="0.00001" iyz="0" izz="0.00001"/>
    </inertial>
  </link>
  <!-- Revolute Joint (opens/closes) -->
  <joint name="finger2_level1_joint" type="revolute">
    <parent link="finger2_base"/>
    <child link="finger2_level1_link"/>
    <origin rpy="0 0 0" xyz="0 0 0"/>
    <axis xyz="0 1 0"/>
    <limit effort="50" lower="0" upper="0.2094" velocity="1.0"/>
    <mimic joint="finger1_level1_joint" multiplier="1.0" offset="0.0"/>
    <dynamics damping="0.1" friction="0.0"/>
  </joint>
  <link name="finger2_level1_link">
    <inertial>
      <origin rpy="0 0 0" xyz="0 0 0"/>
      <mass value="0.01"/>
      <inertia ixx="0.00001" ixy="0" ixz="0" iyy="0.00001" iyz="0" izz="0.00001"/>
    </inertial>
  </link>
  <!-- Fixed H distance to disc -->
  <joint name="finger2_level1_fixed" type="fixed">
    <parent link="finger2_level1_link"/>
    <child link="finger2_level1_disc"/>
    <origin rpy="0 0 0" xyz="0 0 0.022"/>
  </joint>
  <!-- Disc -->
  <link name="finger2_level1_disc">
    <visual>
      <origin rpy="0 0 0" xyz="0 0 0"/>
      <geometry>
        <cylinder length="0.012" radius="0.015"/>
      </geometry>
      <material name="finger2_mat">
        <color rgba="0.2 0.9 0.5 1.0"/>
      </material>
    </visual>
    <collision>
      <origin rpy="0 0 0" xyz="0 0 0"/>
      <geometry>
        <cylinder length="0.012" radius="0.015"/>
      </geometry>
    </collision>
    <inertial>
      <origin rpy="0 0 0" xyz="0 0 0"/>
      <mass value="0.1"/>
      <inertia ixx="0.0001" ixy="0" ixz="0" iyy="0.0001" iyz="0" izz="0.0001"/>
    </inertial>
  </link>
  <!-- Revolute Joint (opens/closes) -->
  <joint name="finger2_level2_joint" type="revolute">
    <parent link="finger2_level1_disc"/>
    <child link="finger2_level2_link"/>
    <origin rpy="0 0 0" xyz="0 0 0"/>
    <axis xyz="0 1 0"/>
    <limit effort="50" lower="0" upper="0.2094" velocity="1.0"/>
    <mimic joint="finger1_level1_joint" multiplier="1.0" offset="0.0"/>
    <dynamics damping="0.1" friction="0.0"/>
  </joint>
  <link name="finger2_level2_link">
    <inertial>
      <origin rpy="0 0 0" xyz="0 0 0"/>
      <mass value="0.01"/>
      <inertia ixx="0.00001" ixy="0" ixz="0" iyy="0.00001" iyz="0" izz="0.00001"/>
    </inertial>
  </link>
  <!-- Fixed H distance to disc -->
  <joint name="finger2_level2_fixed" type="fixed">
    <parent link="finger2_level2_link"/>
    <child link="finger2_level2_disc"/>
    <origin rpy="0 0 0" xyz="0 0 0.022"/>
  </joint>
  <!-- Disc -->
  <link name="finger2_level2_disc">
    <visual>
      <origin rpy="0 0 0" xyz="0 0 0"/>
      <geometry>
        <cylinder length="0.012" radius="0.01375"/>
      </geometry>
      <material name="finger2_mat">
        <color rgba="0.2 0.9 0.5 1.0"/>
      </material>
    </visual>
    <collision>
      <origin rpy="0 0 0" xyz="0 0 0"/>
      <geometry>
        <cylinder length="0.012" radius="0.01375"/>
      </geometry>
    </collision>
    <inertial>
      <origin rpy="0 0 0" xyz="0 0 0"/>
      <mass value="0.1"/>
      <inertia ixx="0.0001" ixy="0" ixz="0" iyy="0.0001" iyz="0" izz="0.0001"/>
    </inertial>
  </link>
  <!-- Revolute Joint (opens/closes) -->
  <joint name="finger2_level3_joint" type="revolute">
    <parent link="finger2_level2_disc"/>
    <child link="finger2_level3_link"/>
    <origin rpy="0 0 0" xyz="0 0 0"/>
    <axis xyz="0 1 0"/>
    <limit effort="50" lower="0" upper="0.2094" velocity="1.0"/>
    <mimic joint="finger1_level1_joint" multiplier="1.0" offset="0.0"/>
    <dynamics damping="0.1" friction="0.0"/>
  </joint>
  <link name="finger2_level3_link">
    <inertial>
      <origin rpy="0 0 0" xyz="0 0 0"/>
      <mass value="0.01"/>
      <inertia ixx="0.00001" ixy="0" ixz="0" iyy="0.00001" iyz="0" izz="0.00001"/>
    </inertial>
  </link>
  <!-- Fixed H distance to disc -->
  <joint name="finger2_level3_fixed" type="fixed">
    <parent link="finger2_level3_link"/>
    <child link="finger2_level3_disc"/>
    <origin rpy="0 0 0" xyz="0 0 0.022"/>
  </joint>
  <!-- Disc -->
  <link name="finger2_level3_disc">
    <visual>
      <origin rpy="0 0 0" xyz="0 0 0"/>
      <geometry>
        <cylinder length="0.012" radius="0.012499999999999999"/>
      </geometry>
      <material name="finger2_mat">
        <color rgba="0.2 0.9 0.5 1.0"/>
      </material>
    </visual>
    <collision>
      <origin rpy="0 0 0" xyz="0 0 0"/>
      <geometry>
        <cylinder length="0.012" radius="0.012499999999999999"/>
      </geometry>
    </collision>
    <inertial>
      <origin rpy="0 0 0" xyz="0 0 0"/>
      <mass value="0.1"/>
      <inertia ixx="0.0001" ixy="0" ixz="0" iyy="0.0001" iyz="0" izz="0.0001"/>
    </inertial>
  </link>
  <!-- Revolute Joint (opens/closes) -->
  <joint name="finger2_level4_joint" type="revolute">
    <parent link="finger2_level3_disc"/>
    <child link="finger2_level4_link"/>
    <origin rpy="0 0 0" xyz="0 0 0"/>
    <axis xyz="0 1 0"/>
    <limit effort="50" lower="0" upper="0.2094" velocity="1.0"/>
    <mimic joint="finger1_level1_joint" multiplier="1.0" offset="0.0"/>
    <dynamics damping="0.1" friction="0.0"/>
  </joint>
  <link name="finger2_level4_link">
    <inertial>
      <origin rpy="0 0 0" xyz="0 0 0"/>
      <mass value="0.01"/>
      <inertia ixx="0.00001" ixy="0" ixz="0" iyy="0.00001" iyz="0" izz="0.00001"/>
    </inertial>
  </link>
  <!-- Fixed H distance to disc -->
  <joint name="finger2_level4_fixed" type="fixed">
    <parent link="finger2_level4_link"/>
    <child link="finger2_level4_disc"/>
    <origin rpy="0 0 0" xyz="0 0 0.022"/>
  </joint>
  <!-- Disc -->
  <link name="finger2_level4_disc">
    <visual>
      <origin rpy="0 0 0" xyz="0 0 0"/>
      <geometry>
        <cylinder length="0.012" radius="0.01125"/>
      </geometry>
      <material name="finger2_mat">
        <color rgba="0.2 0.9 0.5 1.0"/>
      </material>
    </visual>
    <collision>
      <origin rpy="0 0 0" xyz="0 0 0"/>
      <geometry>
        <cylinder length="0.012" radius="0.01125"/>
      </geometry>
    </collision>
    <inertial>
      <origin rpy="0 0 0" xyz="0 0 0"/>
      <mass value="0.1"/>
      <inertia ixx="0.0001" ixy="0" ixz="0" iyy="0.0001" iyz="0" izz="0.0001"/>
    </inertial>
  </link>
  <!-- Revolute Joint (opens/closes) -->
  <joint name="finger2_level5_joint" type="revolute">
    <parent link="finger2_level4_disc"/>
    <child link="finger2_level5_link"/>
    <origin rpy="0 0 0" xyz="0 0 0"/>
    <axis xyz="0 1 0"/>
    <limit effort="50" lower="0" upper="0.2094" velocity="1.0"/>
    <mimic joint="finger1_level1_joint" multiplier="1.0" offset="0.0"/>
    <dynamics damping="0.1" friction="0.0"/>
  </joint>
  <link name="finger2_level5_link">
    <inertial>
      <origin rpy="0 0 0" xyz="0 0 0"/>
      <mass value="0.01"/>
      <inertia ixx="0.00001" ixy="0" ixz="0" iyy="0.00001" iyz="0" izz="0.00001"/>
    </inertial>
  </link>
  <!-- Fixed H distance to disc -->
  <joint name="finger2_level5_fixed" type="fixed">
    <parent link="finger2_level5_link"/>
    <child link="finger2_level5_disc"/>
    <origin rpy="0 0 0" xyz="0 0 0.022"/>
  </joint>
  <!-- Disc -->
  <link name="finger2_level5_disc">
    <visual>
      <origin rpy="0 0 0" xyz="0 0 0"/>
      <geometry>
        <cylinder length="0.012" radius="0.009999999999999998"/>
      </geometry>
      <material name="finger2_mat">
        <color rgba="0.2 0.9 0.5 1.0"/>
      </material>
    </visual>
    <collision>
      <origin rpy="0 0 0" xyz="0 0 0"/>
      <geometry>
        <cylinder length="0.012" radius="0.009999999999999998"/>
      </geometry>
    </collision>
    <inertial>
      <origin rpy="0 0 0" xyz="0 0 0"/>
      <mass value="0.1"/>
      <inertia ixx="0.0001" ixy="0" ixz="0" iyy="0.0001" iyz="0" izz="0.0001"/>
    </inertial>
  </link>
  <!-- Revolute Joint (opens/closes) -->
  <joint name="finger2_level6_joint" type="revolute">
    <parent link="finger2_level5_disc"/>
    <child link="finger2_level6_link"/>
    <origin rpy="0 0 0" xyz="0 0 0"/>
    <axis xyz="0 1 0"/>
    <limit effort="50" lower="0" upper="0.2094" velocity="1.0"/>
    <mimic joint="finger1_level1_joint" multiplier="1.0" offset="0.0"/>
    <dynamics damping="0.1" friction="0.0"/>
  </joint>
  <link name="finger2_level6_link">
    <inertial>
      <origin rpy="0 0 0" xyz="0 0 0"/>
      <mass value="0.01"/>
      <inertia ixx="0.00001" ixy="0" ixz="0" iyy="0.00001" iyz="0" izz="0.00001"/>
    </inertial>
  </link>
  <!-- Fixed H distance to disc -->
  <joint name="finger2_level6_fixed" type="fixed">
    <parent link="finger2_level6_link"/>
    <child link="finger2_level6_disc"/>
    <origin rpy="0 0 0" xyz="0 0 0.022"/>
  </joint>
  <!-- Disc -->
  <link name="finger2_level6_disc">
    <visual>
      <origin rpy="0 0 0" xyz="0 0 0"/>
      <geometry>
        <cylinder length="0.012" radius="0.00875"/>
      </geometry>
      <material name="finger2_mat">
        <color rgba="0.2 0.9 0.5 1.0"/>
      </material>
    </visual>
    <collision>
      <origin rpy="0 0 0" xyz="0 0 0"/>
      <geometry>
        <cylinder length="0.012" radius="0.00875"/>
      </geometry>
    </collision>
    <inertial>
      <origin rpy="0 0 0" xyz="0 0 0"/>
      <mass value="0.1"/>
      <inertia ixx="0.0001" ixy="0" ixz="0" iyy="0.0001" iyz="0" izz="0.0001"/>
    </inertial>
  </link>
  <!-- Revolute Joint (opens/closes) -->
  <joint name="finger2_level7_joint" type="revolute">
    <parent link="finger2_level6_disc"/>
    <child link="finger2_level7_link"/>
    <origin rpy="0 0 0" xyz="0 0 0"/>
    <axis xyz="0 1 0"/>
    <limit effort="50" lower="0" upper="0.2094" velocity="1.0"/>
    <mimic joint="finger1_level1_joint" multiplier="1.0" offset="0.0"/>
    <dynamics damping="0.1" friction="0.0"/>
  </joint>
  <link name="finger2_level7_link">
    <inertial>
      <origin rpy="0 0 0" xyz="0 0 0"/>
      <mass value="0.01"/>
      <inertia ixx="0.00001" ixy="0" ixz="0" iyy="0.00001" iyz="0" izz="0.00001"/>
    </inertial>
  </link>
  <!-- Fixed H distance to disc -->
  <joint name="finger2_level7_fixed" type="fixed">
    <parent link="finger2_level7_link"/>
    <child link="finger2_level7_disc"/>
    <origin rpy="0 0 0" xyz="0 0 0.022"/>
  </joint>
  <!-- Disc -->
  <link name="finger2_level7_disc">
    <visual>
      <origin rpy="0 0 0" xyz="0 0 0"/>
      <geometry>
        <cylinder length="0.012" radius="0.0075"/>
      </geometry>
      <material name="finger2_mat">
        <color rgba="0.2 0.9 0.5 1.0"/>
      </material>
    </visual>
    <collision>
      <origin rpy="0 0 0" xyz="0 0 0"/>
      <geometry>
        <cylinder length="0.012" radius="0.0075"/>
      </geometry>
    </collision>
    <inertial>
      <origin rpy="0 0 0" xyz="0 0 0"/>
      <mass value="0.1"/>
      <inertia ixx="0.0001" ixy="0" ixz="0" iyy="0.0001" iyz="0" izz="0.0001"/>
    </inertial>
  </link>
  <!-- ===== FINGER 3 (at 240°) ===== -->
  <joint name="finger3_mount" type="fixed">
    <parent link="gripper_base"/>
    <child link="finger3_base"/>
    <origin rpy="0 0 4.1888" xyz="-0.010999813375588245 -0.01905266662969333 0"/>
  </joint>
  <link name="finger3_base">
    <inertial>
      <mass value="0.01"/>
      <inertia ixx="0.00001" ixy="0" ixz="0" iyy="0.00001" iyz="0" izz="0.00001"/>
    </inertial>
  </link>
  <!-- Revolute Joint (opens/closes) -->
  <joint name="finger3_level1_joint" type="revolute">
    <parent link="finger3_base"/>
    <child link="finger3_level1_link"/>
    <origin rpy="0 0 0" xyz="0 0 0"/>
    <axis xyz="0 1 0"/>
    <limit effort="50" lower="0" upper="0.2094" velocity="1.0"/>
    <mimic joint="finger1_level1_joint" multiplier="1.0" offset="0.0"/>
    <dynamics damping="0.1" friction="0.0"/>
  </joint>
  <link name="finger3_level1_link">
    <inertial>
      <origin rpy="0 0 0" xyz="0 0 0"/>
      <mass value="0.01"/>
      <inertia ixx="0.00001" ixy="0" ixz="0" iyy="0.00001" iyz="0" izz="0.00001"/>
    </inertial>
  </link>
  <!-- Fixed H distance to disc -->
  <joint name="finger3_level1_fixed" type="fixed">
    <parent link="finger3_level1_link"/>
    <child link="finger3_level1_disc"/>
    <origin rpy="0 0 0" xyz="0 0 0.022"/>
  </joint>
  <!-- Disc -->
  <link name="finger3_level1_disc">
    <visual>
      <origin rpy="0 0 0" xyz="0 0 0"/>
      <geometry>
        <cylinder length="0.012" radius="0.015"/>
      </geometry>
      <material name="finger3_mat">
        <color rgba="0.2 0.9 0.5 1.0"/>
      </material>
    </visual>
    <collision>
      <origin rpy="0 0 0" xyz="0 0 0"/>
      <geometry>
        <cylinder length="0.012" radius="0.015"/>
      </geometry>
    </collision>
    <inertial>
      <origin rpy="0 0 0" xyz="0 0 0"/>
      <mass value="0.1"/>
      <inertia ixx="0.0001" ixy="0" ixz="0" iyy="0.0001" iyz="0" izz="0.0001"/>
    </inertial>
  </link>
  <!-- Revolute Joint (opens/closes) -->
  <joint name="finger3_level2_joint" type="revolute">
    <parent link="finger3_level1_disc"/>
    <child link="finger3_level2_link"/>
    <origin rpy="0 0 0" xyz="0 0 0"/>
    <axis xyz="0 1 0"/>
    <limit effort="50" lower="0" upper="0.2094" velocity="1.0"/>
    <mimic joint="finger1_level1_joint" multiplier="1.0" offset="0.0"/>
    <dynamics damping="0.1" friction="0.0"/>
  </joint>
  <link name="finger3_level2_link">
    <inertial>
      <origin rpy="0 0 0" xyz="0 0 0"/>
      <mass value="0.01"/>
      <inertia ixx="0.00001" ixy="0" ixz="0" iyy="0.00001" iyz="0" izz="0.00001"/>
    </inertial>
  </link>
  <!-- Fixed H distance to disc -->
  <joint name="finger3_level2_fixed" type="fixed">
    <parent link="finger3_level2_link"/>
    <child link="finger3_level2_disc"/>
    <origin rpy="0 0 0" xyz="0 0 0.022"/>
  </joint>
  <!-- Disc -->
  <link name="finger3_level2_disc">
    <visual>
      <origin rpy="0 0 0" xyz="0 0 0"/>
      <geometry>
        <cylinder length="0.012" radius="0.01375"/>
      </geometry>
      <material name="finger3_mat">
        <color rgba="0.2 0.9 0.5 1.0"/>
      </material>
    </visual>
    <collision>
      <origin rpy="0 0 0" xyz="0 0 0"/>
      <geometry>
        <cylinder length="0.012" radius="0.01375"/>
      </geometry>
    </collision>
    <inertial>
      <origin rpy="0 0 0" xyz="0 0 0"/>
      <mass value="0.1"/>
      <inertia ixx="0.0001" ixy="0" ixz="0" iyy="0.0001" iyz="0" izz="0.0001"/>
    </inertial>
  </link>
  <!-- Revolute Joint (opens/closes) -->
  <joint name="finger3_level3_joint" type="revolute">
    <parent link="finger3_level2_disc"/>
    <child link="finger3_level3_link"/>
    <origin rpy="0 0 0" xyz="0 0 0"/>
    <axis xyz="0 1 0"/>
    <limit effort="50" lower="0" upper="0.2094" velocity="1.0"/>
    <mimic joint="finger1_level1_joint" multiplier="1.0" offset="0.0"/>
    <dynamics damping="0.1" friction="0.0"/>
  </joint>
  <link name="finger3_level3_link">
    <inertial>
      <origin rpy="0 0 0" xyz="0 0 0"/>
      <mass value="0.01"/>
      <inertia ixx="0.00001" ixy="0" ixz="0" iyy="0.00001" iyz="0" izz="0.00001"/>
    </inertial>
  </link>
  <!-- Fixed H distance to disc -->
  <joint name="finger3_level3_fixed" type="fixed">
    <parent link="finger3_level3_link"/>
    <child link="finger3_level3_disc"/>
    <origin rpy="0 0 0" xyz="0 0 0.022"/>
  </joint>
  <!-- Disc -->
  <link name="finger3_level3_disc">
    <visual>
      <origin rpy="0 0 0" xyz="0 0 0"/>
      <geometry>
        <cylinder length="0.012" radius="0.012499999999999999"/>
      </geometry>
      <material name="finger3_mat">
        <color rgba="0.2 0.9 0.5 1.0"/>
      </material>
    </visual>
    <collision>
      <origin rpy="0 0 0" xyz="0 0 0"/>
      <geometry>
        <cylinder length="0.012" radius="0.012499999999999999"/>
      </geometry>
    </collision>
    <inertial>
      <origin rpy="0 0 0" xyz="0 0 0"/>
      <mass value="0.1"/>
      <inertia ixx="0.0001" ixy="0" ixz="0" iyy="0.0001" iyz="0" izz="0.0001"/>
    </inertial>
  </link>
  <!-- Revolute Joint (opens/closes) -->
  <joint name="finger3_level4_joint" type="revolute">
    <parent link="finger3_level3_disc"/>
    <child link="finger3_level4_link"/>
    <origin rpy="0 0 0" xyz="0 0 0"/>
    <axis xyz="0 1 0"/>
    <limit effort="50" lower="0" upper="0.2094" velocity="1.0"/>
    <mimic joint="finger1_level1_joint" multiplier="1.0" offset="0.0"/>
    <dynamics damping="0.1" friction="0.0"/>
  </joint>
  <link name="finger3_level4_link">
    <inertial>
      <origin rpy="0 0 0" xyz="0 0 0"/>
      <mass value="0.01"/>
      <inertia ixx="0.00001" ixy="0" ixz="0" iyy="0.00001" iyz="0" izz="0.00001"/>
    </inertial>
  </link>
  <!-- Fixed H distance to disc -->
  <joint name="finger3_level4_fixed" type="fixed">
    <parent link="finger3_level4_link"/>
    <child link="finger3_level4_disc"/>
    <origin rpy="0 0 0" xyz="0 0 0.022"/>
  </joint>
  <!-- Disc -->
  <link name="finger3_level4_disc">
    <visual>
      <origin rpy="0 0 0" xyz="0 0 0"/>
      <geometry>
        <cylinder length="0.012" radius="0.01125"/>
      </geometry>
      <material name="finger3_mat">
        <color rgba="0.2 0.9 0.5 1.0"/>
      </material>
    </visual>
    <collision>
      <origin rpy="0 0 0" xyz="0 0 0"/>
      <geometry>
        <cylinder length="0.012" radius="0.01125"/>
      </geometry>
    </collision>
    <inertial>
      <origin rpy="0 0 0" xyz="0 0 0"/>
      <mass value="0.1"/>
      <inertia ixx="0.0001" ixy="0" ixz="0" iyy="0.0001" iyz="0" izz="0.0001"/>
    </inertial>
  </link>
  <!-- Revolute Joint (opens/closes) -->
  <joint name="finger3_level5_joint" type="revolute">
    <parent link="finger3_level4_disc"/>
    <child link="finger3_level5_link"/>
    <origin rpy="0 0 0" xyz="0 0 0"/>
    <axis xyz="0 1 0"/>
    <limit effort="50" lower="0" upper="0.2094" velocity="1.0"/>
    <mimic joint="finger1_level1_joint" multiplier="1.0" offset="0.0"/>
    <dynamics damping="0.1" friction="0.0"/>
  </joint>
  <link name="finger3_level5_link">
    <inertial>
      <origin rpy="0 0 0" xyz="0 0 0"/>
      <mass value="0.01"/>
      <inertia ixx="0.00001" ixy="0" ixz="0" iyy="0.00001" iyz="0" izz="0.00001"/>
    </inertial>
  </link>
  <!-- Fixed H distance to disc -->
  <joint name="finger3_level5_fixed" type="fixed">
    <parent link="finger3_level5_link"/>
    <child link="finger3_level5_disc"/>
    <origin rpy="0 0 0" xyz="0 0 0.022"/>
  </joint>
  <!-- Disc -->
  <link name="finger3_level5_disc">
    <visual>
      <origin rpy="0 0 0" xyz="0 0 0"/>
      <geometry>
        <cylinder length="0.012" radius="0.009999999999999998"/>
      </geometry>
      <material name="finger3_mat">
        <color rgba="0.2 0.9 0.5 1.0"/>
      </material>
    </visual>
    <collision>
      <origin rpy="0 0 0" xyz="0 0 0"/>
      <geometry>
        <cylinder length="0.012" radius="0.009999999999999998"/>
      </geometry>
    </collision>
    <inertial>
      <origin rpy="0 0 0" xyz="0 0 0"/>
      <mass value="0.1"/>
      <inertia ixx="0.0001" ixy="0" ixz="0" iyy="0.0001" iyz="0" izz="0.0001"/>
    </inertial>
  </link>
  <!-- Revolute Joint (opens/closes) -->
  <joint name="finger3_level6_joint" type="revolute">
    <parent link="finger3_level5_disc"/>
    <child link="finger3_level6_link"/>
    <origin rpy="0 0 0" xyz="0 0 0"/>
    <axis xyz="0 1 0"/>
    <limit effort="50" lower="0" upper="0.2094" velocity="1.0"/>
    <mimic joint="finger1_level1_joint" multiplier="1.0" offset="0.0"/>
    <dynamics damping="0.1" friction="0.0"/>
  </joint>
  <link name="finger3_level6_link">
    <inertial>
      <origin rpy="0 0 0" xyz="0 0 0"/>
      <mass value="0.01"/>
      <inertia ixx="0.00001" ixy="0" ixz="0" iyy="0.00001" iyz="0" izz="0.00001"/>
    </inertial>
  </link>
  <!-- Fixed H distance to disc -->
  <joint name="finger3_level6_fixed" type="fixed">
    <parent link="finger3_level6_link"/>
    <child link="finger3_level6_disc"/>
    <origin rpy="0 0 0" xyz="0 0 0.022"/>
  </joint>
  <!-- Disc -->
  <link name="finger3_level6_disc">
    <visual>
      <origin rpy="0 0 0" xyz="0 0 0"/>
      <geometry>
        <cylinder length="0.012" radius="0.00875"/>
      </geometry>
      <material name="finger3_mat">
        <color rgba="0.2 0.9 0.5 1.0"/>
      </material>
    </visual>
    <collision>
      <origin rpy="0 0 0" xyz="0 0 0"/>
      <geometry>
        <cylinder length="0.012" radius="0.00875"/>
      </geometry>
    </collision>
    <inertial>
      <origin rpy="0 0 0" xyz="0 0 0"/>
      <mass value="0.1"/>
      <inertia ixx="0.0001" ixy="0" ixz="0" iyy="0.0001" iyz="0" izz="0.0001"/>
    </inertial>
  </link>
  <!-- Revolute Joint (opens/closes) -->
  <joint name="finger3_level7_joint" type="revolute">
    <parent link="finger3_level6_disc"/>
    <child link="finger3_level7_link"/>
    <origin rpy="0 0 0" xyz="0 0 0"/>
    <axis xyz="0 1 0"/>
    <limit effort="50" lower="0" upper="0.2094" velocity="1.0"/>
    <mimic joint="finger1_level1_joint" multiplier="1.0" offset="0.0"/>
    <dynamics damping="0.1" friction="0.0"/>
  </joint>
  <link name="finger3_level7_link">
    <inertial>
      <origin rpy="0 0 0" xyz="0 0 0"/>
      <mass value="0.01"/>
      <inertia ixx="0.00001" ixy="0" ixz="0" iyy="0.00001" iyz="0" izz="0.00001"/>
    </inertial>
  </link>
  <!-- Fixed H distance to disc -->
  <joint name="finger3_level7_fixed" type="fixed">
    <parent link="finger3_level7_link"/>
    <child link="finger3_level7_disc"/>
    <origin rpy="0 0 0" xyz="0 0 0.022"/>
  </joint>
  <!-- Disc -->
  <link name="finger3_level7_disc">
    <visual>
      <origin rpy="0 0 0" xyz="0 0 0"/>
      <geometry>
        <cylinder length="0.012" radius="0.0075"/>
      </geometry>
      <material name="finger3_mat">
        <color rgba="0.2 0.9 0.5 1.0"/>
      </material>
    </visual>
    <collision>
      <origin rpy="0 0 0" xyz="0 0 0"/>
      <geometry>
        <cylinder length="0.012" radius="0.0075"/>
      </geometry>
    </collision>
    <inertial>
      <origin rpy="0 0 0" xyz="0 0 0"/>
      <mass value="0.1"/>
      <inertia ixx="0.0001" ixy="0" ixz="0" iyy="0.0001" iyz="0" izz="0.0001"/>
    </inertial>
  </link>
</robot>
