<?xml version="1.0" ?>
<!-- =================================================================================== -->
<!-- |    This document was autogenerated by xacro from two_segment_gripper.xacro      | -->
<!-- |    EDITING THIS FILE BY HAND IS NOT RECOMMENDED                                 | -->
<!-- =================================================================================== -->
<robot name="two_segment_gripper">
  <!-- 12mm disc thickness -->
  <!-- 22mm from center -->
  <!-- Base Link -->
  <link name="base_link">
    <visual>
      <origin rpy="0 0 0" xyz="0 0 0.04"/>
      <geometry>
        <box size="0.2 0.2 0.08"/>
      </geometry>
      <material name="brown">
        <color rgba="0.6 0.4 0.2 1.0"/>
      </material>
    </visual>
    <collision>
      <origin rpy="0 0 0" xyz="0 0 0.04"/>
      <geometry>
        <box size="0.2 0.2 0.08"/>
      </geometry>
    </collision>
    <inertial>
      <origin rpy="0 0 0" xyz="0 0 0.04"/>
      <mass value="2.0"/>
      <inertia ixx="0.01" ixy="0" ixz="0" iyy="0.01" iyz="0" izz="0.01"/>
    </inertial>
  </link>
  <!-- Gripper Base -->
  <joint name="base_to_gripper" type="fixed">
    <parent link="base_link"/>
    <child link="gripper_base"/>
    <origin rpy="0 0 0" xyz="0 0 0.08"/>
  </joint>
  <link name="gripper_base">
    <visual>
      <origin rpy="0 0 0" xyz="0 0 0.005"/>
      <geometry>
        <cylinder length="0.01" radius="0.04"/>
      </geometry>
      <material name="gray">
        <color rgba="0.5 0.5 0.5 1.0"/>
      </material>
    </visual>
    <inertial>
      <mass value="0.2"/>
      <inertia ixx="0.0001" ixy="0" ixz="0" iyy="0.0001" iyz="0" izz="0.0001"/>
    </inertial>
  </link>
  <!-- ===== FINGER 1 (at 0°) ===== -->
  <joint name="finger1_mount" type="fixed">
    <parent link="gripper_base"/>
    <child link="finger1_base"/>
    <origin rpy="0 0 0" xyz="0.022 0 0.01"/>
  </joint>
  <link name="finger1_base">
    <inertial>
      <mass value="0.01"/>
      <inertia ixx="0.00001" ixy="0" ixz="0" iyy="0.00001" iyz="0" izz="0.00001"/>
    </inertial>
  </link>
  <!-- Revolute Joint -->
  <joint name="finger1_seg1_joint" type="revolute">
    <parent link="finger1_base"/>
    <child link="finger1_seg1_link"/>
    <origin rpy="0 0 0" xyz="0 0 0"/>
    <axis xyz="0 1 0"/>
    <limit effort="50" lower="-0.0175" upper="0.2094" velocity="1.0"/>
    <dynamics damping="0.5" friction="0.0"/>
  </joint>
  <link name="finger1_seg1_link">
    <inertial>
      <origin rpy="0 0 0" xyz="0 0 0"/>
      <mass value="0.01"/>
      <inertia ixx="0.00001" ixy="0" ixz="0" iyy="0.00001" iyz="0" izz="0.00001"/>
    </inertial>
  </link>
  <!-- Fixed H distance to disc -->
  <joint name="finger1_seg1_fixed" type="fixed">
    <parent link="finger1_seg1_link"/>
    <child link="finger1_seg1_disc"/>
    <origin rpy="0 0 0" xyz="0 0 0.022"/>
  </joint>
  <!-- Disc -->
  <link name="finger1_seg1_disc">
    <visual>
      <origin rpy="0 0 0" xyz="0 0 0"/>
      <geometry>
        <cylinder length="0.012" radius="0.015"/>
      </geometry>
      <material name="finger_seg1_mat">
        <color rgba="0.2 0.9 0.5 1.0"/>
      </material>
    </visual>
    <collision>
      <origin rpy="0 0 0" xyz="0 0 0"/>
      <geometry>
        <cylinder length="0.012" radius="0.015"/>
      </geometry>
    </collision>
    <inertial>
      <origin rpy="0 0 0" xyz="0 0 0"/>
      <mass value="0.1"/>
      <inertia ixx="0.0001" ixy="0" ixz="0" iyy="0.0001" iyz="0" izz="0.0001"/>
    </inertial>
  </link>
  <!-- Revolute Joint -->
  <joint name="finger1_seg2_joint" type="revolute">
    <parent link="finger1_seg1_disc"/>
    <child link="finger1_seg2_link"/>
    <origin rpy="0 0 0" xyz="0 0 0"/>
    <axis xyz="0 1 0"/>
    <limit effort="50" lower="-0.0175" upper="0.2094" velocity="1.0"/>
    <mimic joint="finger1_seg1_joint" multiplier="1.0" offset="0.0"/>
    <dynamics damping="0.1" friction="0.0"/>
  </joint>
  <link name="finger1_seg2_link">
    <inertial>
      <origin rpy="0 0 0" xyz="0 0 0"/>
      <mass value="0.01"/>
      <inertia ixx="0.00001" ixy="0" ixz="0" iyy="0.00001" iyz="0" izz="0.00001"/>
    </inertial>
  </link>
  <!-- Fixed H distance to disc -->
  <joint name="finger1_seg2_fixed" type="fixed">
    <parent link="finger1_seg2_link"/>
    <child link="finger1_seg2_disc"/>
    <origin rpy="0 0 0" xyz="0 0 0.022"/>
  </joint>
  <!-- Disc -->
  <link name="finger1_seg2_disc">
    <visual>
      <origin rpy="0 0 0" xyz="0 0 0"/>
      <geometry>
        <cylinder length="0.012" radius="0.014062499999999999"/>
      </geometry>
      <material name="finger_seg2_mat">
        <color rgba="0.2 0.9 0.5 1.0"/>
      </material>
    </visual>
    <collision>
      <origin rpy="0 0 0" xyz="0 0 0"/>
      <geometry>
        <cylinder length="0.012" radius="0.014062499999999999"/>
      </geometry>
    </collision>
    <inertial>
      <origin rpy="0 0 0" xyz="0 0 0"/>
      <mass value="0.1"/>
      <inertia ixx="0.0001" ixy="0" ixz="0" iyy="0.0001" iyz="0" izz="0.0001"/>
    </inertial>
  </link>
  <!-- Revolute Joint -->
  <joint name="finger1_seg3_joint" type="revolute">
    <parent link="finger1_seg2_disc"/>
    <child link="finger1_seg3_link"/>
    <origin rpy="0 0 0" xyz="0 0 0"/>
    <axis xyz="0 1 0"/>
    <limit effort="50" lower="-0.0175" upper="0.2094" velocity="1.0"/>
    <mimic joint="finger1_seg1_joint" multiplier="1.0" offset="0.0"/>
    <dynamics damping="0.1" friction="0.0"/>
  </joint>
  <link name="finger1_seg3_link">
    <inertial>
      <origin rpy="0 0 0" xyz="0 0 0"/>
      <mass value="0.01"/>
      <inertia ixx="0.00001" ixy="0" ixz="0" iyy="0.00001" iyz="0" izz="0.00001"/>
    </inertial>
  </link>
  <!-- Fixed H distance to disc -->
  <joint name="finger1_seg3_fixed" type="fixed">
    <parent link="finger1_seg3_link"/>
    <child link="finger1_seg3_disc"/>
    <origin rpy="0 0 0" xyz="0 0 0.022"/>
  </joint>
  <!-- Disc -->
  <link name="finger1_seg3_disc">
    <visual>
      <origin rpy="0 0 0" xyz="0 0 0"/>
      <geometry>
        <cylinder length="0.012" radius="0.013125"/>
      </geometry>
      <material name="finger_seg3_mat">
        <color rgba="0.2 0.9 0.5 1.0"/>
      </material>
    </visual>
    <collision>
      <origin rpy="0 0 0" xyz="0 0 0"/>
      <geometry>
        <cylinder length="0.012" radius="0.013125"/>
      </geometry>
    </collision>
    <inertial>
      <origin rpy="0 0 0" xyz="0 0 0"/>
      <mass value="0.1"/>
      <inertia ixx="0.0001" ixy="0" ixz="0" iyy="0.0001" iyz="0" izz="0.0001"/>
    </inertial>
  </link>
  <!-- Revolute Joint -->
  <joint name="finger1_seg4_joint" type="revolute">
    <parent link="finger1_seg3_disc"/>
    <child link="finger1_seg4_link"/>
    <origin rpy="0 0 0" xyz="0 0 0"/>
    <axis xyz="0 1 0"/>
    <limit effort="50" lower="-0.0175" upper="0.2094" velocity="1.0"/>
    <mimic joint="finger1_seg1_joint" multiplier="1.0" offset="0.0"/>
    <dynamics damping="0.1" friction="0.0"/>
  </joint>
  <link name="finger1_seg4_link">
    <inertial>
      <origin rpy="0 0 0" xyz="0 0 0"/>
      <mass value="0.01"/>
      <inertia ixx="0.00001" ixy="0" ixz="0" iyy="0.00001" iyz="0" izz="0.00001"/>
    </inertial>
  </link>
  <!-- Fixed H distance to disc -->
  <joint name="finger1_seg4_fixed" type="fixed">
    <parent link="finger1_seg4_link"/>
    <child link="finger1_seg4_disc"/>
    <origin rpy="0 0 0" xyz="0 0 0.022"/>
  </joint>
  <!-- Disc -->
  <link name="finger1_seg4_disc">
    <visual>
      <origin rpy="0 0 0" xyz="0 0 0"/>
      <geometry>
        <cylinder length="0.012" radius="0.0121875"/>
      </geometry>
      <material name="finger_seg4_mat">
        <color rgba="0.2 0.9 0.5 1.0"/>
      </material>
    </visual>
    <collision>
      <origin rpy="0 0 0" xyz="0 0 0"/>
      <geometry>
        <cylinder length="0.012" radius="0.0121875"/>
      </geometry>
    </collision>
    <inertial>
      <origin rpy="0 0 0" xyz="0 0 0"/>
      <mass value="0.1"/>
      <inertia ixx="0.0001" ixy="0" ixz="0" iyy="0.0001" iyz="0" izz="0.0001"/>
    </inertial>
  </link>
  <!-- Revolute Joint -->
  <joint name="finger1_seg5_joint" type="revolute">
    <parent link="finger1_seg4_disc"/>
    <child link="finger1_seg5_link"/>
    <origin rpy="0 0 0" xyz="0 0 0"/>
    <axis xyz="0 1 0"/>
    <limit effort="50" lower="-0.0175" upper="0.2094" velocity="1.0"/>
    <mimic joint="finger1_seg1_joint" multiplier="1.0" offset="0.0"/>
    <dynamics damping="0.1" friction="0.0"/>
  </joint>
  <link name="finger1_seg5_link">
    <inertial>
      <origin rpy="0 0 0" xyz="0 0 0"/>
      <mass value="0.01"/>
      <inertia ixx="0.00001" ixy="0" ixz="0" iyy="0.00001" iyz="0" izz="0.00001"/>
    </inertial>
  </link>
  <!-- Fixed H distance to disc -->
  <joint name="finger1_seg5_fixed" type="fixed">
    <parent link="finger1_seg5_link"/>
    <child link="finger1_seg5_disc"/>
    <origin rpy="0 0 0" xyz="0 0 0.022"/>
  </joint>
  <!-- Disc -->
  <link name="finger1_seg5_disc">
    <visual>
      <origin rpy="0 0 0" xyz="0 0 0"/>
      <geometry>
        <cylinder length="0.012" radius="0.01125"/>
      </geometry>
      <material name="finger_seg5_mat">
        <color rgba="0.2 0.9 0.5 1.0"/>
      </material>
    </visual>
    <collision>
      <origin rpy="0 0 0" xyz="0 0 0"/>
      <geometry>
        <cylinder length="0.012" radius="0.01125"/>
      </geometry>
    </collision>
    <inertial>
      <origin rpy="0 0 0" xyz="0 0 0"/>
      <mass value="0.1"/>
      <inertia ixx="0.0001" ixy="0" ixz="0" iyy="0.0001" iyz="0" izz="0.0001"/>
    </inertial>
  </link>
  <!-- Revolute Joint -->
  <joint name="finger1_seg6_joint" type="revolute">
    <parent link="finger1_seg5_disc"/>
    <child link="finger1_seg6_link"/>
    <origin rpy="0 0 0" xyz="0 0 0"/>
    <axis xyz="0 1 0"/>
    <limit effort="50" lower="-0.1047" upper="0.2094" velocity="1.0"/>
    <dynamics damping="0.5" friction="0.0"/>
  </joint>
  <link name="finger1_seg6_link">
    <inertial>
      <origin rpy="0 0 0" xyz="0 0 0"/>
      <mass value="0.01"/>
      <inertia ixx="0.00001" ixy="0" ixz="0" iyy="0.00001" iyz="0" izz="0.00001"/>
    </inertial>
  </link>
  <!-- Fixed H distance to disc -->
  <joint name="finger1_seg6_fixed" type="fixed">
    <parent link="finger1_seg6_link"/>
    <child link="finger1_seg6_disc"/>
    <origin rpy="0 0 0" xyz="0 0 0.022"/>
  </joint>
  <!-- Disc -->
  <link name="finger1_seg6_disc">
    <visual>
      <origin rpy="0 0 0" xyz="0 0 0"/>
      <geometry>
        <cylinder length="0.012" radius="0.01125"/>
      </geometry>
      <material name="finger_seg6_mat">
        <color rgba="0.2 0.8 0.9 1.0"/>
      </material>
    </visual>
    <collision>
      <origin rpy="0 0 0" xyz="0 0 0"/>
      <geometry>
        <cylinder length="0.012" radius="0.01125"/>
      </geometry>
    </collision>
    <inertial>
      <origin rpy="0 0 0" xyz="0 0 0"/>
      <mass value="0.1"/>
      <inertia ixx="0.0001" ixy="0" ixz="0" iyy="0.0001" iyz="0" izz="0.0001"/>
    </inertial>
  </link>
  <!-- Revolute Joint -->
  <joint name="finger1_seg7_joint" type="revolute">
    <parent link="finger1_seg6_disc"/>
    <child link="finger1_seg7_link"/>
    <origin rpy="0 0 0" xyz="0 0 0"/>
    <axis xyz="0 1 0"/>
    <limit effort="50" lower="-0.1047" upper="0.2094" velocity="1.0"/>
    <mimic joint="finger1_seg6_joint" multiplier="1.0" offset="0.0"/>
    <dynamics damping="0.1" friction="0.0"/>
  </joint>
  <link name="finger1_seg7_link">
    <inertial>
      <origin rpy="0 0 0" xyz="0 0 0"/>
      <mass value="0.01"/>
      <inertia ixx="0.00001" ixy="0" ixz="0" iyy="0.00001" iyz="0" izz="0.00001"/>
    </inertial>
  </link>
  <!-- Fixed H distance to disc -->
  <joint name="finger1_seg7_fixed" type="fixed">
    <parent link="finger1_seg7_link"/>
    <child link="finger1_seg7_disc"/>
    <origin rpy="0 0 0" xyz="0 0 0.022"/>
  </joint>
  <!-- Disc -->
  <link name="finger1_seg7_disc">
    <visual>
      <origin rpy="0 0 0" xyz="0 0 0"/>
      <geometry>
        <cylinder length="0.012" radius="0.010312499999999999"/>
      </geometry>
      <material name="finger_seg7_mat">
        <color rgba="0.2 0.8 0.9 1.0"/>
      </material>
    </visual>
    <collision>
      <origin rpy="0 0 0" xyz="0 0 0"/>
      <geometry>
        <cylinder length="0.012" radius="0.010312499999999999"/>
      </geometry>
    </collision>
    <inertial>
      <origin rpy="0 0 0" xyz="0 0 0"/>
      <mass value="0.1"/>
      <inertia ixx="0.0001" ixy="0" ixz="0" iyy="0.0001" iyz="0" izz="0.0001"/>
    </inertial>
  </link>
  <!-- Revolute Joint -->
  <joint name="finger1_seg8_joint" type="revolute">
    <parent link="finger1_seg7_disc"/>
    <child link="finger1_seg8_link"/>
    <origin rpy="0 0 0" xyz="0 0 0"/>
    <axis xyz="0 1 0"/>
    <limit effort="50" lower="-0.1047" upper="0.2094" velocity="1.0"/>
    <mimic joint="finger1_seg6_joint" multiplier="1.0" offset="0.0"/>
    <dynamics damping="0.1" friction="0.0"/>
  </joint>
  <link name="finger1_seg8_link">
    <inertial>
      <origin rpy="0 0 0" xyz="0 0 0"/>
      <mass value="0.01"/>
      <inertia ixx="0.00001" ixy="0" ixz="0" iyy="0.00001" iyz="0" izz="0.00001"/>
    </inertial>
  </link>
  <!-- Fixed H distance to disc -->
  <joint name="finger1_seg8_fixed" type="fixed">
    <parent link="finger1_seg8_link"/>
    <child link="finger1_seg8_disc"/>
    <origin rpy="0 0 0" xyz="0 0 0.022"/>
  </joint>
  <!-- Disc -->
  <link name="finger1_seg8_disc">
    <visual>
      <origin rpy="0 0 0" xyz="0 0 0"/>
      <geometry>
        <cylinder length="0.012" radius="0.009375"/>
      </geometry>
      <material name="finger_seg8_mat">
        <color rgba="0.2 0.8 0.9 1.0"/>
      </material>
    </visual>
    <collision>
      <origin rpy="0 0 0" xyz="0 0 0"/>
      <geometry>
        <cylinder length="0.012" radius="0.009375"/>
      </geometry>
    </collision>
    <inertial>
      <origin rpy="0 0 0" xyz="0 0 0"/>
      <mass value="0.1"/>
      <inertia ixx="0.0001" ixy="0" ixz="0" iyy="0.0001" iyz="0" izz="0.0001"/>
    </inertial>
  </link>
  <!-- Revolute Joint -->
  <joint name="finger1_seg9_joint" type="revolute">
    <parent link="finger1_seg8_disc"/>
    <child link="finger1_seg9_link"/>
    <origin rpy="0 0 0" xyz="0 0 0"/>
    <axis xyz="0 1 0"/>
    <limit effort="50" lower="-0.1047" upper="0.2094" velocity="1.0"/>
    <mimic joint="finger1_seg6_joint" multiplier="1.0" offset="0.0"/>
    <dynamics damping="0.1" friction="0.0"/>
  </joint>
  <link name="finger1_seg9_link">
    <inertial>
      <origin rpy="0 0 0" xyz="0 0 0"/>
      <mass value="0.01"/>
      <inertia ixx="0.00001" ixy="0" ixz="0" iyy="0.00001" iyz="0" izz="0.00001"/>
    </inertial>
  </link>
  <!-- Fixed H distance to disc -->
  <joint name="finger1_seg9_fixed" type="fixed">
    <parent link="finger1_seg9_link"/>
    <child link="finger1_seg9_disc"/>
    <origin rpy="0 0 0" xyz="0 0 0.022"/>
  </joint>
  <!-- Disc -->
  <link name="finger1_seg9_disc">
    <visual>
      <origin rpy="0 0 0" xyz="0 0 0"/>
      <geometry>
        <cylinder length="0.012" radius="0.0084375"/>
      </geometry>
      <material name="finger_seg9_mat">
        <color rgba="0.2 0.8 0.9 1.0"/>
      </material>
    </visual>
    <collision>
      <origin rpy="0 0 0" xyz="0 0 0"/>
      <geometry>
        <cylinder length="0.012" radius="0.0084375"/>
      </geometry>
    </collision>
    <inertial>
      <origin rpy="0 0 0" xyz="0 0 0"/>
      <mass value="0.1"/>
      <inertia ixx="0.0001" ixy="0" ixz="0" iyy="0.0001" iyz="0" izz="0.0001"/>
    </inertial>
  </link>
  <!-- Revolute Joint -->
  <joint name="finger1_seg10_joint" type="revolute">
    <parent link="finger1_seg9_disc"/>
    <child link="finger1_seg10_link"/>
    <origin rpy="0 0 0" xyz="0 0 0"/>
    <axis xyz="0 1 0"/>
    <limit effort="50" lower="-0.1047" upper="0.2094" velocity="1.0"/>
    <mimic joint="finger1_seg6_joint" multiplier="1.0" offset="0.0"/>
    <dynamics damping="0.1" friction="0.0"/>
  </joint>
  <link name="finger1_seg10_link">
    <inertial>
      <origin rpy="0 0 0" xyz="0 0 0"/>
      <mass value="0.01"/>
      <inertia ixx="0.00001" ixy="0" ixz="0" iyy="0.00001" iyz="0" izz="0.00001"/>
    </inertial>
  </link>
  <!-- Fixed H distance to disc -->
  <joint name="finger1_seg10_fixed" type="fixed">
    <parent link="finger1_seg10_link"/>
    <child link="finger1_seg10_disc"/>
    <origin rpy="0 0 0" xyz="0 0 0.022"/>
  </joint>
  <!-- Disc -->
  <link name="finger1_seg10_disc">
    <visual>
      <origin rpy="0 0 0" xyz="0 0 0"/>
      <geometry>
        <cylinder length="0.012" radius="0.0075"/>
      </geometry>
      <material name="finger_seg10_mat">
        <color rgba="0.2 0.8 0.9 1.0"/>
      </material>
    </visual>
    <collision>
      <origin rpy="0 0 0" xyz="0 0 0"/>
      <geometry>
        <cylinder length="0.012" radius="0.0075"/>
      </geometry>
    </collision>
    <inertial>
      <origin rpy="0 0 0" xyz="0 0 0"/>
      <mass value="0.1"/>
      <inertia ixx="0.0001" ixy="0" ixz="0" iyy="0.0001" iyz="0" izz="0.0001"/>
    </inertial>
  </link>
  <!-- ===== FINGER 2 (at 120°) ===== -->
  <joint name="finger2_mount" type="fixed">
    <parent link="gripper_base"/>
    <child link="finger2_base"/>
    <origin rpy="0 0 2.0944" xyz="-0.0110000933118101 0.0190525050093543 0.01"/>
  </joint>
  <link name="finger2_base">
    <inertial>
      <mass value="0.01"/>
      <inertia ixx="0.00001" ixy="0" ixz="0" iyy="0.00001" iyz="0" izz="0.00001"/>
    </inertial>
  </link>
  <!-- Revolute Joint -->
  <joint name="finger2_seg1_joint" type="revolute">
    <parent link="finger2_base"/>
    <child link="finger2_seg1_link"/>
    <origin rpy="0 0 0" xyz="0 0 0"/>
    <axis xyz="0 1 0"/>
    <limit effort="50" lower="-0.0175" upper="0.2094" velocity="1.0"/>
    <mimic joint="finger1_seg1_joint" multiplier="1.0" offset="0.0"/>
    <dynamics damping="0.1" friction="0.0"/>
  </joint>
  <link name="finger2_seg1_link">
    <inertial>
      <origin rpy="0 0 0" xyz="0 0 0"/>
      <mass value="0.01"/>
      <inertia ixx="0.00001" ixy="0" ixz="0" iyy="0.00001" iyz="0" izz="0.00001"/>
    </inertial>
  </link>
  <!-- Fixed H distance to disc -->
  <joint name="finger2_seg1_fixed" type="fixed">
    <parent link="finger2_seg1_link"/>
    <child link="finger2_seg1_disc"/>
    <origin rpy="0 0 0" xyz="0 0 0.022"/>
  </joint>
  <!-- Disc -->
  <link name="finger2_seg1_disc">
    <visual>
      <origin rpy="0 0 0" xyz="0 0 0"/>
      <geometry>
        <cylinder length="0.012" radius="0.015"/>
      </geometry>
      <material name="finger_seg1_mat">
        <color rgba="0.2 0.9 0.5 1.0"/>
      </material>
    </visual>
    <collision>
      <origin rpy="0 0 0" xyz="0 0 0"/>
      <geometry>
        <cylinder length="0.012" radius="0.015"/>
      </geometry>
    </collision>
    <inertial>
      <origin rpy="0 0 0" xyz="0 0 0"/>
      <mass value="0.1"/>
      <inertia ixx="0.0001" ixy="0" ixz="0" iyy="0.0001" iyz="0" izz="0.0001"/>
    </inertial>
  </link>
  <!-- Revolute Joint -->
  <joint name="finger2_seg2_joint" type="revolute">
    <parent link="finger2_seg1_disc"/>
    <child link="finger2_seg2_link"/>
    <origin rpy="0 0 0" xyz="0 0 0"/>
    <axis xyz="0 1 0"/>
    <limit effort="50" lower="-0.0175" upper="0.2094" velocity="1.0"/>
    <mimic joint="finger1_seg1_joint" multiplier="1.0" offset="0.0"/>
    <dynamics damping="0.1" friction="0.0"/>
  </joint>
  <link name="finger2_seg2_link">
    <inertial>
      <origin rpy="0 0 0" xyz="0 0 0"/>
      <mass value="0.01"/>
      <inertia ixx="0.00001" ixy="0" ixz="0" iyy="0.00001" iyz="0" izz="0.00001"/>
    </inertial>
  </link>
  <!-- Fixed H distance to disc -->
  <joint name="finger2_seg2_fixed" type="fixed">
    <parent link="finger2_seg2_link"/>
    <child link="finger2_seg2_disc"/>
    <origin rpy="0 0 0" xyz="0 0 0.022"/>
  </joint>
  <!-- Disc -->
  <link name="finger2_seg2_disc">
    <visual>
      <origin rpy="0 0 0" xyz="0 0 0"/>
      <geometry>
        <cylinder length="0.012" radius="0.014062499999999999"/>
      </geometry>
      <material name="finger_seg2_mat">
        <color rgba="0.2 0.9 0.5 1.0"/>
      </material>
    </visual>
    <collision>
      <origin rpy="0 0 0" xyz="0 0 0"/>
      <geometry>
        <cylinder length="0.012" radius="0.014062499999999999"/>
      </geometry>
    </collision>
    <inertial>
      <origin rpy="0 0 0" xyz="0 0 0"/>
      <mass value="0.1"/>
      <inertia ixx="0.0001" ixy="0" ixz="0" iyy="0.0001" iyz="0" izz="0.0001"/>
    </inertial>
  </link>
  <!-- Revolute Joint -->
  <joint name="finger2_seg3_joint" type="revolute">
    <parent link="finger2_seg2_disc"/>
    <child link="finger2_seg3_link"/>
    <origin rpy="0 0 0" xyz="0 0 0"/>
    <axis xyz="0 1 0"/>
    <limit effort="50" lower="-0.0175" upper="0.2094" velocity="1.0"/>
    <mimic joint="finger1_seg1_joint" multiplier="1.0" offset="0.0"/>
    <dynamics damping="0.1" friction="0.0"/>
  </joint>
  <link name="finger2_seg3_link">
    <inertial>
      <origin rpy="0 0 0" xyz="0 0 0"/>
      <mass value="0.01"/>
      <inertia ixx="0.00001" ixy="0" ixz="0" iyy="0.00001" iyz="0" izz="0.00001"/>
    </inertial>
  </link>
  <!-- Fixed H distance to disc -->
  <joint name="finger2_seg3_fixed" type="fixed">
    <parent link="finger2_seg3_link"/>
    <child link="finger2_seg3_disc"/>
    <origin rpy="0 0 0" xyz="0 0 0.022"/>
  </joint>
  <!-- Disc -->
  <link name="finger2_seg3_disc">
    <visual>
      <origin rpy="0 0 0" xyz="0 0 0"/>
      <geometry>
        <cylinder length="0.012" radius="0.013125"/>
      </geometry>
      <material name="finger_seg3_mat">
        <color rgba="0.2 0.9 0.5 1.0"/>
      </material>
    </visual>
    <collision>
      <origin rpy="0 0 0" xyz="0 0 0"/>
      <geometry>
        <cylinder length="0.012" radius="0.013125"/>
      </geometry>
    </collision>
    <inertial>
      <origin rpy="0 0 0" xyz="0 0 0"/>
      <mass value="0.1"/>
      <inertia ixx="0.0001" ixy="0" ixz="0" iyy="0.0001" iyz="0" izz="0.0001"/>
    </inertial>
  </link>
  <!-- Revolute Joint -->
  <joint name="finger2_seg4_joint" type="revolute">
    <parent link="finger2_seg3_disc"/>
    <child link="finger2_seg4_link"/>
    <origin rpy="0 0 0" xyz="0 0 0"/>
    <axis xyz="0 1 0"/>
    <limit effort="50" lower="-0.0175" upper="0.2094" velocity="1.0"/>
    <mimic joint="finger1_seg1_joint" multiplier="1.0" offset="0.0"/>
    <dynamics damping="0.1" friction="0.0"/>
  </joint>
  <link name="finger2_seg4_link">
    <inertial>
      <origin rpy="0 0 0" xyz="0 0 0"/>
      <mass value="0.01"/>
      <inertia ixx="0.00001" ixy="0" ixz="0" iyy="0.00001" iyz="0" izz="0.00001"/>
    </inertial>
  </link>
  <!-- Fixed H distance to disc -->
  <joint name="finger2_seg4_fixed" type="fixed">
    <parent link="finger2_seg4_link"/>
    <child link="finger2_seg4_disc"/>
    <origin rpy="0 0 0" xyz="0 0 0.022"/>
  </joint>
  <!-- Disc -->
  <link name="finger2_seg4_disc">
    <visual>
      <origin rpy="0 0 0" xyz="0 0 0"/>
      <geometry>
        <cylinder length="0.012" radius="0.0121875"/>
      </geometry>
      <material name="finger_seg4_mat">
        <color rgba="0.2 0.9 0.5 1.0"/>
      </material>
    </visual>
    <collision>
      <origin rpy="0 0 0" xyz="0 0 0"/>
      <geometry>
        <cylinder length="0.012" radius="0.0121875"/>
      </geometry>
    </collision>
    <inertial>
      <origin rpy="0 0 0" xyz="0 0 0"/>
      <mass value="0.1"/>
      <inertia ixx="0.0001" ixy="0" ixz="0" iyy="0.0001" iyz="0" izz="0.0001"/>
    </inertial>
  </link>
  <!-- Revolute Joint -->
  <joint name="finger2_seg5_joint" type="revolute">
    <parent link="finger2_seg4_disc"/>
    <child link="finger2_seg5_link"/>
    <origin rpy="0 0 0" xyz="0 0 0"/>
    <axis xyz="0 1 0"/>
    <limit effort="50" lower="-0.0175" upper="0.2094" velocity="1.0"/>
    <mimic joint="finger1_seg1_joint" multiplier="1.0" offset="0.0"/>
    <dynamics damping="0.1" friction="0.0"/>
  </joint>
  <link name="finger2_seg5_link">
    <inertial>
      <origin rpy="0 0 0" xyz="0 0 0"/>
      <mass value="0.01"/>
      <inertia ixx="0.00001" ixy="0" ixz="0" iyy="0.00001" iyz="0" izz="0.00001"/>
    </inertial>
  </link>
  <!-- Fixed H distance to disc -->
  <joint name="finger2_seg5_fixed" type="fixed">
    <parent link="finger2_seg5_link"/>
    <child link="finger2_seg5_disc"/>
    <origin rpy="0 0 0" xyz="0 0 0.022"/>
  </joint>
  <!-- Disc -->
  <link name="finger2_seg5_disc">
    <visual>
      <origin rpy="0 0 0" xyz="0 0 0"/>
      <geometry>
        <cylinder length="0.012" radius="0.01125"/>
      </geometry>
      <material name="finger_seg5_mat">
        <color rgba="0.2 0.9 0.5 1.0"/>
      </material>
    </visual>
    <collision>
      <origin rpy="0 0 0" xyz="0 0 0"/>
      <geometry>
        <cylinder length="0.012" radius="0.01125"/>
      </geometry>
    </collision>
    <inertial>
      <origin rpy="0 0 0" xyz="0 0 0"/>
      <mass value="0.1"/>
      <inertia ixx="0.0001" ixy="0" ixz="0" iyy="0.0001" iyz="0" izz="0.0001"/>
    </inertial>
  </link>
  <!-- Revolute Joint -->
  <joint name="finger2_seg6_joint" type="revolute">
    <parent link="finger2_seg5_disc"/>
    <child link="finger2_seg6_link"/>
    <origin rpy="0 0 0" xyz="0 0 0"/>
    <axis xyz="0 1 0"/>
    <limit effort="50" lower="-0.1047" upper="0.2094" velocity="1.0"/>
    <mimic joint="finger1_seg6_joint" multiplier="1.0" offset="0.0"/>
    <dynamics damping="0.1" friction="0.0"/>
  </joint>
  <link name="finger2_seg6_link">
    <inertial>
      <origin rpy="0 0 0" xyz="0 0 0"/>
      <mass value="0.01"/>
      <inertia ixx="0.00001" ixy="0" ixz="0" iyy="0.00001" iyz="0" izz="0.00001"/>
    </inertial>
  </link>
  <!-- Fixed H distance to disc -->
  <joint name="finger2_seg6_fixed" type="fixed">
    <parent link="finger2_seg6_link"/>
    <child link="finger2_seg6_disc"/>
    <origin rpy="0 0 0" xyz="0 0 0.022"/>
  </joint>
  <!-- Disc -->
  <link name="finger2_seg6_disc">
    <visual>
      <origin rpy="0 0 0" xyz="0 0 0"/>
      <geometry>
        <cylinder length="0.012" radius="0.01125"/>
      </geometry>
      <material name="finger_seg6_mat">
        <color rgba="0.2 0.8 0.9 1.0"/>
      </material>
    </visual>
    <collision>
      <origin rpy="0 0 0" xyz="0 0 0"/>
      <geometry>
        <cylinder length="0.012" radius="0.01125"/>
      </geometry>
    </collision>
    <inertial>
      <origin rpy="0 0 0" xyz="0 0 0"/>
      <mass value="0.1"/>
      <inertia ixx="0.0001" ixy="0" ixz="0" iyy="0.0001" iyz="0" izz="0.0001"/>
    </inertial>
  </link>
  <!-- Revolute Joint -->
  <joint name="finger2_seg7_joint" type="revolute">
    <parent link="finger2_seg6_disc"/>
    <child link="finger2_seg7_link"/>
    <origin rpy="0 0 0" xyz="0 0 0"/>
    <axis xyz="0 1 0"/>
    <limit effort="50" lower="-0.1047" upper="0.2094" velocity="1.0"/>
    <mimic joint="finger1_seg6_joint" multiplier="1.0" offset="0.0"/>
    <dynamics damping="0.1" friction="0.0"/>
  </joint>
  <link name="finger2_seg7_link">
    <inertial>
      <origin rpy="0 0 0" xyz="0 0 0"/>
      <mass value="0.01"/>
      <inertia ixx="0.00001" ixy="0" ixz="0" iyy="0.00001" iyz="0" izz="0.00001"/>
    </inertial>
  </link>
  <!-- Fixed H distance to disc -->
  <joint name="finger2_seg7_fixed" type="fixed">
    <parent link="finger2_seg7_link"/>
    <child link="finger2_seg7_disc"/>
    <origin rpy="0 0 0" xyz="0 0 0.022"/>
  </joint>
  <!-- Disc -->
  <link name="finger2_seg7_disc">
    <visual>
      <origin rpy="0 0 0" xyz="0 0 0"/>
      <geometry>
        <cylinder length="0.012" radius="0.010312499999999999"/>
      </geometry>
      <material name="finger_seg7_mat">
        <color rgba="0.2 0.8 0.9 1.0"/>
      </material>
    </visual>
    <collision>
      <origin rpy="0 0 0" xyz="0 0 0"/>
      <geometry>
        <cylinder length="0.012" radius="0.010312499999999999"/>
      </geometry>
    </collision>
    <inertial>
      <origin rpy="0 0 0" xyz="0 0 0"/>
      <mass value="0.1"/>
      <inertia ixx="0.0001" ixy="0" ixz="0" iyy="0.0001" iyz="0" izz="0.0001"/>
    </inertial>
  </link>
  <!-- Revolute Joint -->
  <joint name="finger2_seg8_joint" type="revolute">
    <parent link="finger2_seg7_disc"/>
    <child link="finger2_seg8_link"/>
    <origin rpy="0 0 0" xyz="0 0 0"/>
    <axis xyz="0 1 0"/>
    <limit effort="50" lower="-0.1047" upper="0.2094" velocity="1.0"/>
    <mimic joint="finger1_seg6_joint" multiplier="1.0" offset="0.0"/>
    <dynamics damping="0.1" friction="0.0"/>
  </joint>
  <link name="finger2_seg8_link">
    <inertial>
      <origin rpy="0 0 0" xyz="0 0 0"/>
      <mass value="0.01"/>
      <inertia ixx="0.00001" ixy="0" ixz="0" iyy="0.00001" iyz="0" izz="0.00001"/>
    </inertial>
  </link>
  <!-- Fixed H distance to disc -->
  <joint name="finger2_seg8_fixed" type="fixed">
    <parent link="finger2_seg8_link"/>
    <child link="finger2_seg8_disc"/>
    <origin rpy="0 0 0" xyz="0 0 0.022"/>
  </joint>
  <!-- Disc -->
  <link name="finger2_seg8_disc">
    <visual>
      <origin rpy="0 0 0" xyz="0 0 0"/>
      <geometry>
        <cylinder length="0.012" radius="0.009375"/>
      </geometry>
      <material name="finger_seg8_mat">
        <color rgba="0.2 0.8 0.9 1.0"/>
      </material>
    </visual>
    <collision>
      <origin rpy="0 0 0" xyz="0 0 0"/>
      <geometry>
        <cylinder length="0.012" radius="0.009375"/>
      </geometry>
    </collision>
    <inertial>
      <origin rpy="0 0 0" xyz="0 0 0"/>
      <mass value="0.1"/>
      <inertia ixx="0.0001" ixy="0" ixz="0" iyy="0.0001" iyz="0" izz="0.0001"/>
    </inertial>
  </link>
  <!-- Revolute Joint -->
  <joint name="finger2_seg9_joint" type="revolute">
    <parent link="finger2_seg8_disc"/>
    <child link="finger2_seg9_link"/>
    <origin rpy="0 0 0" xyz="0 0 0"/>
    <axis xyz="0 1 0"/>
    <limit effort="50" lower="-0.1047" upper="0.2094" velocity="1.0"/>
    <mimic joint="finger1_seg6_joint" multiplier="1.0" offset="0.0"/>
    <dynamics damping="0.1" friction="0.0"/>
  </joint>
  <link name="finger2_seg9_link">
    <inertial>
      <origin rpy="0 0 0" xyz="0 0 0"/>
      <mass value="0.01"/>
      <inertia ixx="0.00001" ixy="0" ixz="0" iyy="0.00001" iyz="0" izz="0.00001"/>
    </inertial>
  </link>
  <!-- Fixed H distance to disc -->
  <joint name="finger2_seg9_fixed" type="fixed">
    <parent link="finger2_seg9_link"/>
    <child link="finger2_seg9_disc"/>
    <origin rpy="0 0 0" xyz="0 0 0.022"/>
  </joint>
  <!-- Disc -->
  <link name="finger2_seg9_disc">
    <visual>
      <origin rpy="0 0 0" xyz="0 0 0"/>
      <geometry>
        <cylinder length="0.012" radius="0.0084375"/>
      </geometry>
      <material name="finger_seg9_mat">
        <color rgba="0.2 0.8 0.9 1.0"/>
      </material>
    </visual>
    <collision>
      <origin rpy="0 0 0" xyz="0 0 0"/>
      <geometry>
        <cylinder length="0.012" radius="0.0084375"/>
      </geometry>
    </collision>
    <inertial>
      <origin rpy="0 0 0" xyz="0 0 0"/>
      <mass value="0.1"/>
      <inertia ixx="0.0001" ixy="0" ixz="0" iyy="0.0001" iyz="0" izz="0.0001"/>
    </inertial>
  </link>
  <!-- Revolute Joint -->
  <joint name="finger2_seg10_joint" type="revolute">
    <parent link="finger2_seg9_disc"/>
    <child link="finger2_seg10_link"/>
    <origin rpy="0 0 0" xyz="0 0 0"/>
    <axis xyz="0 1 0"/>
    <limit effort="50" lower="-0.1047" upper="0.2094" velocity="1.0"/>
    <mimic joint="finger1_seg6_joint" multiplier="1.0" offset="0.0"/>
    <dynamics damping="0.1" friction="0.0"/>
  </joint>
  <link name="finger2_seg10_link">
    <inertial>
      <origin rpy="0 0 0" xyz="0 0 0"/>
      <mass value="0.01"/>
      <inertia ixx="0.00001" ixy="0" ixz="0" iyy="0.00001" iyz="0" izz="0.00001"/>
    </inertial>
  </link>
  <!-- Fixed H distance to disc -->
  <joint name="finger2_seg10_fixed" type="fixed">
    <parent link="finger2_seg10_link"/>
    <child link="finger2_seg10_disc"/>
    <origin rpy="0 0 0" xyz="0 0 0.022"/>
  </joint>
  <!-- Disc -->
  <link name="finger2_seg10_disc">
    <visual>
      <origin rpy="0 0 0" xyz="0 0 0"/>
      <geometry>
        <cylinder length="0.012" radius="0.0075"/>
      </geometry>
      <material name="finger_seg10_mat">
        <color rgba="0.2 0.8 0.9 1.0"/>
      </material>
    </visual>
    <collision>
      <origin rpy="0 0 0" xyz="0 0 0"/>
      <geometry>
        <cylinder length="0.012" radius="0.0075"/>
      </geometry>
    </collision>
    <inertial>
      <origin rpy="0 0 0" xyz="0 0 0"/>
      <mass value="0.1"/>
      <inertia ixx="0.0001" ixy="0" ixz="0" iyy="0.0001" iyz="0" izz="0.0001"/>
    </inertial>
  </link>
  <!-- ===== FINGER 3 (at 240°) ===== -->
  <joint name="finger3_mount" type="fixed">
    <parent link="gripper_base"/>
    <child link="finger3_base"/>
    <origin rpy="0 0 4.1888" xyz="-0.010999813375588245 -0.01905266662969333 0.01"/>
  </joint>
  <link name="finger3_base">
    <inertial>
      <mass value="0.01"/>
      <inertia ixx="0.00001" ixy="0" ixz="0" iyy="0.00001" iyz="0" izz="0.00001"/>
    </inertial>
  </link>
  <!-- Revolute Joint -->
  <joint name="finger3_seg1_joint" type="revolute">
    <parent link="finger3_base"/>
    <child link="finger3_seg1_link"/>
    <origin rpy="0 0 0" xyz="0 0 0"/>
    <axis xyz="0 1 0"/>
    <limit effort="50" lower="-0.0175" upper="0.2094" velocity="1.0"/>
    <mimic joint="finger1_seg1_joint" multiplier="1.0" offset="0.0"/>
    <dynamics damping="0.1" friction="0.0"/>
  </joint>
  <link name="finger3_seg1_link">
    <inertial>
      <origin rpy="0 0 0" xyz="0 0 0"/>
      <mass value="0.01"/>
      <inertia ixx="0.00001" ixy="0" ixz="0" iyy="0.00001" iyz="0" izz="0.00001"/>
    </inertial>
  </link>
  <!-- Fixed H distance to disc -->
  <joint name="finger3_seg1_fixed" type="fixed">
    <parent link="finger3_seg1_link"/>
    <child link="finger3_seg1_disc"/>
    <origin rpy="0 0 0" xyz="0 0 0.022"/>
  </joint>
  <!-- Disc -->
  <link name="finger3_seg1_disc">
    <visual>
      <origin rpy="0 0 0" xyz="0 0 0"/>
      <geometry>
        <cylinder length="0.012" radius="0.015"/>
      </geometry>
      <material name="finger_seg1_mat">
        <color rgba="0.2 0.9 0.5 1.0"/>
      </material>
    </visual>
    <collision>
      <origin rpy="0 0 0" xyz="0 0 0"/>
      <geometry>
        <cylinder length="0.012" radius="0.015"/>
      </geometry>
    </collision>
    <inertial>
      <origin rpy="0 0 0" xyz="0 0 0"/>
      <mass value="0.1"/>
      <inertia ixx="0.0001" ixy="0" ixz="0" iyy="0.0001" iyz="0" izz="0.0001"/>
    </inertial>
  </link>
  <!-- Revolute Joint -->
  <joint name="finger3_seg2_joint" type="revolute">
    <parent link="finger3_seg1_disc"/>
    <child link="finger3_seg2_link"/>
    <origin rpy="0 0 0" xyz="0 0 0"/>
    <axis xyz="0 1 0"/>
    <limit effort="50" lower="-0.0175" upper="0.2094" velocity="1.0"/>
    <mimic joint="finger1_seg1_joint" multiplier="1.0" offset="0.0"/>
    <dynamics damping="0.1" friction="0.0"/>
  </joint>
  <link name="finger3_seg2_link">
    <inertial>
      <origin rpy="0 0 0" xyz="0 0 0"/>
      <mass value="0.01"/>
      <inertia ixx="0.00001" ixy="0" ixz="0" iyy="0.00001" iyz="0" izz="0.00001"/>
    </inertial>
  </link>
  <!-- Fixed H distance to disc -->
  <joint name="finger3_seg2_fixed" type="fixed">
    <parent link="finger3_seg2_link"/>
    <child link="finger3_seg2_disc"/>
    <origin rpy="0 0 0" xyz="0 0 0.022"/>
  </joint>
  <!-- Disc -->
  <link name="finger3_seg2_disc">
    <visual>
      <origin rpy="0 0 0" xyz="0 0 0"/>
      <geometry>
        <cylinder length="0.012" radius="0.014062499999999999"/>
      </geometry>
      <material name="finger_seg2_mat">
        <color rgba="0.2 0.9 0.5 1.0"/>
      </material>
    </visual>
    <collision>
      <origin rpy="0 0 0" xyz="0 0 0"/>
      <geometry>
        <cylinder length="0.012" radius="0.014062499999999999"/>
      </geometry>
    </collision>
    <inertial>
      <origin rpy="0 0 0" xyz="0 0 0"/>
      <mass value="0.1"/>
      <inertia ixx="0.0001" ixy="0" ixz="0" iyy="0.0001" iyz="0" izz="0.0001"/>
    </inertial>
  </link>
  <!-- Revolute Joint -->
  <joint name="finger3_seg3_joint" type="revolute">
    <parent link="finger3_seg2_disc"/>
    <child link="finger3_seg3_link"/>
    <origin rpy="0 0 0" xyz="0 0 0"/>
    <axis xyz="0 1 0"/>
    <limit effort="50" lower="-0.0175" upper="0.2094" velocity="1.0"/>
    <mimic joint="finger1_seg1_joint" multiplier="1.0" offset="0.0"/>
    <dynamics damping="0.1" friction="0.0"/>
  </joint>
  <link name="finger3_seg3_link">
    <inertial>
      <origin rpy="0 0 0" xyz="0 0 0"/>
      <mass value="0.01"/>
      <inertia ixx="0.00001" ixy="0" ixz="0" iyy="0.00001" iyz="0" izz="0.00001"/>
    </inertial>
  </link>
  <!-- Fixed H distance to disc -->
  <joint name="finger3_seg3_fixed" type="fixed">
    <parent link="finger3_seg3_link"/>
    <child link="finger3_seg3_disc"/>
    <origin rpy="0 0 0" xyz="0 0 0.022"/>
  </joint>
  <!-- Disc -->
  <link name="finger3_seg3_disc">
    <visual>
      <origin rpy="0 0 0" xyz="0 0 0"/>
      <geometry>
        <cylinder length="0.012" radius="0.013125"/>
      </geometry>
      <material name="finger_seg3_mat">
        <color rgba="0.2 0.9 0.5 1.0"/>
      </material>
    </visual>
    <collision>
      <origin rpy="0 0 0" xyz="0 0 0"/>
      <geometry>
        <cylinder length="0.012" radius="0.013125"/>
      </geometry>
    </collision>
    <inertial>
      <origin rpy="0 0 0" xyz="0 0 0"/>
      <mass value="0.1"/>
      <inertia ixx="0.0001" ixy="0" ixz="0" iyy="0.0001" iyz="0" izz="0.0001"/>
    </inertial>
  </link>
  <!-- Revolute Joint -->
  <joint name="finger3_seg4_joint" type="revolute">
    <parent link="finger3_seg3_disc"/>
    <child link="finger3_seg4_link"/>
    <origin rpy="0 0 0" xyz="0 0 0"/>
    <axis xyz="0 1 0"/>
    <limit effort="50" lower="-0.0175" upper="0.2094" velocity="1.0"/>
    <mimic joint="finger1_seg1_joint" multiplier="1.0" offset="0.0"/>
    <dynamics damping="0.1" friction="0.0"/>
  </joint>
  <link name="finger3_seg4_link">
    <inertial>
      <origin rpy="0 0 0" xyz="0 0 0"/>
      <mass value="0.01"/>
      <inertia ixx="0.00001" ixy="0" ixz="0" iyy="0.00001" iyz="0" izz="0.00001"/>
    </inertial>
  </link>
  <!-- Fixed H distance to disc -->
  <joint name="finger3_seg4_fixed" type="fixed">
    <parent link="finger3_seg4_link"/>
    <child link="finger3_seg4_disc"/>
    <origin rpy="0 0 0" xyz="0 0 0.022"/>
  </joint>
  <!-- Disc -->
  <link name="finger3_seg4_disc">
    <visual>
      <origin rpy="0 0 0" xyz="0 0 0"/>
      <geometry>
        <cylinder length="0.012" radius="0.0121875"/>
      </geometry>
      <material name="finger_seg4_mat">
        <color rgba="0.2 0.9 0.5 1.0"/>
      </material>
    </visual>
    <collision>
      <origin rpy="0 0 0" xyz="0 0 0"/>
      <geometry>
        <cylinder length="0.012" radius="0.0121875"/>
      </geometry>
    </collision>
    <inertial>
      <origin rpy="0 0 0" xyz="0 0 0"/>
      <mass value="0.1"/>
      <inertia ixx="0.0001" ixy="0" ixz="0" iyy="0.0001" iyz="0" izz="0.0001"/>
    </inertial>
  </link>
  <!-- Revolute Joint -->
  <joint name="finger3_seg5_joint" type="revolute">
    <parent link="finger3_seg4_disc"/>
    <child link="finger3_seg5_link"/>
    <origin rpy="0 0 0" xyz="0 0 0"/>
    <axis xyz="0 1 0"/>
    <limit effort="50" lower="-0.0175" upper="0.2094" velocity="1.0"/>
    <mimic joint="finger1_seg1_joint" multiplier="1.0" offset="0.0"/>
    <dynamics damping="0.1" friction="0.0"/>
  </joint>
  <link name="finger3_seg5_link">
    <inertial>
      <origin rpy="0 0 0" xyz="0 0 0"/>
      <mass value="0.01"/>
      <inertia ixx="0.00001" ixy="0" ixz="0" iyy="0.00001" iyz="0" izz="0.00001"/>
    </inertial>
  </link>
  <!-- Fixed H distance to disc -->
  <joint name="finger3_seg5_fixed" type="fixed">
    <parent link="finger3_seg5_link"/>
    <child link="finger3_seg5_disc"/>
    <origin rpy="0 0 0" xyz="0 0 0.022"/>
  </joint>
  <!-- Disc -->
  <link name="finger3_seg5_disc">
    <visual>
      <origin rpy="0 0 0" xyz="0 0 0"/>
      <geometry>
        <cylinder length="0.012" radius="0.01125"/>
      </geometry>
      <material name="finger_seg5_mat">
        <color rgba="0.2 0.9 0.5 1.0"/>
      </material>
    </visual>
    <collision>
      <origin rpy="0 0 0" xyz="0 0 0"/>
      <geometry>
        <cylinder length="0.012" radius="0.01125"/>
      </geometry>
    </collision>
    <inertial>
      <origin rpy="0 0 0" xyz="0 0 0"/>
      <mass value="0.1"/>
      <inertia ixx="0.0001" ixy="0" ixz="0" iyy="0.0001" iyz="0" izz="0.0001"/>
    </inertial>
  </link>
  <!-- Revolute Joint -->
  <joint name="finger3_seg6_joint" type="revolute">
    <parent link="finger3_seg5_disc"/>
    <child link="finger3_seg6_link"/>
    <origin rpy="0 0 0" xyz="0 0 0"/>
    <axis xyz="0 1 0"/>
    <limit effort="50" lower="-0.1047" upper="0.2094" velocity="1.0"/>
    <mimic joint="finger1_seg6_joint" multiplier="1.0" offset="0.0"/>
    <dynamics damping="0.1" friction="0.0"/>
  </joint>
  <link name="finger3_seg6_link">
    <inertial>
      <origin rpy="0 0 0" xyz="0 0 0"/>
      <mass value="0.01"/>
      <inertia ixx="0.00001" ixy="0" ixz="0" iyy="0.00001" iyz="0" izz="0.00001"/>
    </inertial>
  </link>
  <!-- Fixed H distance to disc -->
  <joint name="finger3_seg6_fixed" type="fixed">
    <parent link="finger3_seg6_link"/>
    <child link="finger3_seg6_disc"/>
    <origin rpy="0 0 0" xyz="0 0 0.022"/>
  </joint>
  <!-- Disc -->
  <link name="finger3_seg6_disc">
    <visual>
      <origin rpy="0 0 0" xyz="0 0 0"/>
      <geometry>
        <cylinder length="0.012" radius="0.01125"/>
      </geometry>
      <material name="finger_seg6_mat">
        <color rgba="0.2 0.8 0.9 1.0"/>
      </material>
    </visual>
    <collision>
      <origin rpy="0 0 0" xyz="0 0 0"/>
      <geometry>
        <cylinder length="0.012" radius="0.01125"/>
      </geometry>
    </collision>
    <inertial>
      <origin rpy="0 0 0" xyz="0 0 0"/>
      <mass value="0.1"/>
      <inertia ixx="0.0001" ixy="0" ixz="0" iyy="0.0001" iyz="0" izz="0.0001"/>
    </inertial>
  </link>
  <!-- Revolute Joint -->
  <joint name="finger3_seg7_joint" type="revolute">
    <parent link="finger3_seg6_disc"/>
    <child link="finger3_seg7_link"/>
    <origin rpy="0 0 0" xyz="0 0 0"/>
    <axis xyz="0 1 0"/>
    <limit effort="50" lower="-0.1047" upper="0.2094" velocity="1.0"/>
    <mimic joint="finger1_seg6_joint" multiplier="1.0" offset="0.0"/>
    <dynamics damping="0.1" friction="0.0"/>
  </joint>
  <link name="finger3_seg7_link">
    <inertial>
      <origin rpy="0 0 0" xyz="0 0 0"/>
      <mass value="0.01"/>
      <inertia ixx="0.00001" ixy="0" ixz="0" iyy="0.00001" iyz="0" izz="0.00001"/>
    </inertial>
  </link>
  <!-- Fixed H distance to disc -->
  <joint name="finger3_seg7_fixed" type="fixed">
    <parent link="finger3_seg7_link"/>
    <child link="finger3_seg7_disc"/>
    <origin rpy="0 0 0" xyz="0 0 0.022"/>
  </joint>
  <!-- Disc -->
  <link name="finger3_seg7_disc">
    <visual>
      <origin rpy="0 0 0" xyz="0 0 0"/>
      <geometry>
        <cylinder length="0.012" radius="0.010312499999999999"/>
      </geometry>
      <material name="finger_seg7_mat">
        <color rgba="0.2 0.8 0.9 1.0"/>
      </material>
    </visual>
    <collision>
      <origin rpy="0 0 0" xyz="0 0 0"/>
      <geometry>
        <cylinder length="0.012" radius="0.010312499999999999"/>
      </geometry>
    </collision>
    <inertial>
      <origin rpy="0 0 0" xyz="0 0 0"/>
      <mass value="0.1"/>
      <inertia ixx="0.0001" ixy="0" ixz="0" iyy="0.0001" iyz="0" izz="0.0001"/>
    </inertial>
  </link>
  <!-- Revolute Joint -->
  <joint name="finger3_seg8_joint" type="revolute">
    <parent link="finger3_seg7_disc"/>
    <child link="finger3_seg8_link"/>
    <origin rpy="0 0 0" xyz="0 0 0"/>
    <axis xyz="0 1 0"/>
    <limit effort="50" lower="-0.1047" upper="0.2094" velocity="1.0"/>
    <mimic joint="finger1_seg6_joint" multiplier="1.0" offset="0.0"/>
    <dynamics damping="0.1" friction="0.0"/>
  </joint>
  <link name="finger3_seg8_link">
    <inertial>
      <origin rpy="0 0 0" xyz="0 0 0"/>
      <mass value="0.01"/>
      <inertia ixx="0.00001" ixy="0" ixz="0" iyy="0.00001" iyz="0" izz="0.00001"/>
    </inertial>
  </link>
  <!-- Fixed H distance to disc -->
  <joint name="finger3_seg8_fixed" type="fixed">
    <parent link="finger3_seg8_link"/>
    <child link="finger3_seg8_disc"/>
    <origin rpy="0 0 0" xyz="0 0 0.022"/>
  </joint>
  <!-- Disc -->
  <link name="finger3_seg8_disc">
    <visual>
      <origin rpy="0 0 0" xyz="0 0 0"/>
      <geometry>
        <cylinder length="0.012" radius="0.009375"/>
      </geometry>
      <material name="finger_seg8_mat">
        <color rgba="0.2 0.8 0.9 1.0"/>
      </material>
    </visual>
    <collision>
      <origin rpy="0 0 0" xyz="0 0 0"/>
      <geometry>
        <cylinder length="0.012" radius="0.009375"/>
      </geometry>
    </collision>
    <inertial>
      <origin rpy="0 0 0" xyz="0 0 0"/>
      <mass value="0.1"/>
      <inertia ixx="0.0001" ixy="0" ixz="0" iyy="0.0001" iyz="0" izz="0.0001"/>
    </inertial>
  </link>
  <!-- Revolute Joint -->
  <joint name="finger3_seg9_joint" type="revolute">
    <parent link="finger3_seg8_disc"/>
    <child link="finger3_seg9_link"/>
    <origin rpy="0 0 0" xyz="0 0 0"/>
    <axis xyz="0 1 0"/>
    <limit effort="50" lower="-0.1047" upper="0.2094" velocity="1.0"/>
    <mimic joint="finger1_seg6_joint" multiplier="1.0" offset="0.0"/>
    <dynamics damping="0.1" friction="0.0"/>
  </joint>
  <link name="finger3_seg9_link">
    <inertial>
      <origin rpy="0 0 0" xyz="0 0 0"/>
      <mass value="0.01"/>
      <inertia ixx="0.00001" ixy="0" ixz="0" iyy="0.00001" iyz="0" izz="0.00001"/>
    </inertial>
  </link>
  <!-- Fixed H distance to disc -->
  <joint name="finger3_seg9_fixed" type="fixed">
    <parent link="finger3_seg9_link"/>
    <child link="finger3_seg9_disc"/>
    <origin rpy="0 0 0" xyz="0 0 0.022"/>
  </joint>
  <!-- Disc -->
  <link name="finger3_seg9_disc">
    <visual>
      <origin rpy="0 0 0" xyz="0 0 0"/>
      <geometry>
        <cylinder length="0.012" radius="0.0084375"/>
      </geometry>
      <material name="finger_seg9_mat">
        <color rgba="0.2 0.8 0.9 1.0"/>
      </material>
    </visual>
    <collision>
      <origin rpy="0 0 0" xyz="0 0 0"/>
      <geometry>
        <cylinder length="0.012" radius="0.0084375"/>
      </geometry>
    </collision>
    <inertial>
      <origin rpy="0 0 0" xyz="0 0 0"/>
      <mass value="0.1"/>
      <inertia ixx="0.0001" ixy="0" ixz="0" iyy="0.0001" iyz="0" izz="0.0001"/>
    </inertial>
  </link>
  <!-- Revolute Joint -->
  <joint name="finger3_seg10_joint" type="revolute">
    <parent link="finger3_seg9_disc"/>
    <child link="finger3_seg10_link"/>
    <origin rpy="0 0 0" xyz="0 0 0"/>
    <axis xyz="0 1 0"/>
    <limit effort="50" lower="-0.1047" upper="0.2094" velocity="1.0"/>
    <mimic joint="finger1_seg6_joint" multiplier="1.0" offset="0.0"/>
    <dynamics damping="0.1" friction="0.0"/>
  </joint>
  <link name="finger3_seg10_link">
    <inertial>
      <origin rpy="0 0 0" xyz="0 0 0"/>
      <mass value="0.01"/>
      <inertia ixx="0.00001" ixy="0" ixz="0" iyy="0.00001" iyz="0" izz="0.00001"/>
    </inertial>
  </link>
  <!-- Fixed H distance to disc -->
  <joint name="finger3_seg10_fixed" type="fixed">
    <parent link="finger3_seg10_link"/>
    <child link="finger3_seg10_disc"/>
    <origin rpy="0 0 0" xyz="0 0 0.022"/>
  </joint>
  <!-- Disc -->
  <link name="finger3_seg10_disc">
    <visual>
      <origin rpy="0 0 0" xyz="0 0 0"/>
      <geometry>
        <cylinder length="0.012" radius="0.0075"/>
      </geometry>
      <material name="finger_seg10_mat">
        <color rgba="0.2 0.8 0.9 1.0"/>
      </material>
    </visual>
    <collision>
      <origin rpy="0 0 0" xyz="0 0 0"/>
      <geometry>
        <cylinder length="0.012" radius="0.0075"/>
      </geometry>
    </collision>
    <inertial>
      <origin rpy="0 0 0" xyz="0 0 0"/>
      <mass value="0.1"/>
      <inertia ixx="0.0001" ixy="0" ixz="0" iyy="0.0001" iyz="0" izz="0.0001"/>
    </inertial>
  </link>
</robot>
