<?xml version="1.0" ?>
<!-- =================================================================================== -->
<!-- |    This document was autogenerated by xacro from modular_robot_follower.xacro   | -->
<!-- |    EDITING THIS FILE BY HAND IS NOT RECOMMENDED                                 | -->
<!-- =================================================================================== -->
<robot name="follower_serial_robot">
  <!-- 12mm disc thickness -->
  <!-- Base Link -->
  <link name="base_link">
    <visual>
      <origin rpy="0 0 0" xyz="0 0 0.04"/>
      <geometry>
        <box size="0.2 0.2 0.08"/>
      </geometry>
      <material name="brown">
        <color rgba="0.6 0.4 0.2 1.0"/>
      </material>
    </visual>
    <collision>
      <origin rpy="0 0 0" xyz="0 0 0.04"/>
      <geometry>
        <box size="0.2 0.2 0.08"/>
      </geometry>
    </collision>
    <inertial>
      <origin rpy="0 0 0" xyz="0 0 0.04"/>
      <mass value="2.0"/>
      <inertia ixx="0.01" ixy="0" ixz="0" iyy="0.01" iyz="0" izz="0.01"/>
    </inertial>
  </link>
  <!-- Fixed joint from base to first segment mounting point -->
  <joint name="base_to_seg1" type="fixed">
    <parent link="base_link"/>
    <child link="seg1_mount"/>
    <origin rpy="0 0 0" xyz="0 0 0.08"/>
  </joint>
  <link name="seg1_mount">
    <!-- No visual - invisible mounting point -->
    <inertial>
      <mass value="0.01"/>
      <inertia ixx="0.00001" ixy="0" ixz="0" iyy="0.00001" iyz="0" izz="0.00001"/>
    </inertial>
  </link>
  <!-- ===== BOTTOM HALF: 7 segments controlled by seg1 (ORANGE) ===== -->
  <!-- Revolute Joint X (Roll) -->
  <joint name="seg1_joint_x" type="revolute">
    <parent link="seg1_mount"/>
    <child link="seg1_x_link"/>
    <origin rpy="0 0 0" xyz="0 0 0"/>
    <axis xyz="1 0 0"/>
    <limit effort="100" lower="-0.2094" upper="0.2094" velocity="1.0"/>
    <dynamics damping="0.7" friction="0.0"/>
  </joint>
  <link name="seg1_x_link">
    <!-- No visual - invisible joint -->
    <inertial>
      <origin rpy="0 0 0" xyz="0 0 0"/>
      <mass value="0.01"/>
      <inertia ixx="0.00001" ixy="0" ixz="0" iyy="0.00001" iyz="0" izz="0.00001"/>
    </inertial>
  </link>
  <!-- Revolute Joint Y (Pitch) -->
  <joint name="seg1_joint_y" type="revolute">
    <parent link="seg1_x_link"/>
    <child link="seg1_y_link"/>
    <origin rpy="0 0 0" xyz="0 0 0"/>
    <axis xyz="0 1 0"/>
    <limit effort="100" lower="-0.2094" upper="0.2094" velocity="1.0"/>
    <dynamics damping="0.7" friction="0.0"/>
  </joint>
  <link name="seg1_y_link">
    <!-- No visual - invisible joint -->
    <inertial>
      <origin rpy="0 0 0" xyz="0 0 0"/>
      <mass value="0.01"/>
      <inertia ixx="0.00001" ixy="0" ixz="0" iyy="0.00001" iyz="0" izz="0.00001"/>
    </inertial>
  </link>
  <!-- Fixed H distance joint -->
  <joint name="seg1_fixed_h" type="fixed">
    <parent link="seg1_y_link"/>
    <child link="seg1_mid_link"/>
    <origin rpy="0 0 0" xyz="0 0 0.022"/>
  </joint>
  <!-- Middle link with disc platform -->
  <link name="seg1_mid_link">
    <visual>
      <!-- Disc platform only -->
      <origin rpy="0 0 0" xyz="0 0 0"/>
      <geometry>
        <cylinder length="0.012" radius="0.0352"/>
      </geometry>
      <material name="disc_1">
        <color rgba="1.0 0.6 0.2 1.0"/>
      </material>
    </visual>
    <collision>
      <origin rpy="0 0 0" xyz="0 0 0"/>
      <geometry>
        <cylinder length="0.012" radius="0.0352"/>
      </geometry>
    </collision>
    <inertial>
      <origin rpy="0 0 0" xyz="0 0 0"/>
      <mass value="0.5"/>
      <inertia ixx="0.002" ixy="0" ixz="0" iyy="0.002" iyz="0" izz="0.003"/>
    </inertial>
  </link>
  <!-- Revolute Joint X (Roll) -->
  <joint name="seg2_joint_x" type="revolute">
    <parent link="seg1_mid_link"/>
    <child link="seg2_x_link"/>
    <origin rpy="0 0 0" xyz="0 0 0"/>
    <axis xyz="1 0 0"/>
    <limit effort="100" lower="-0.2094" upper="0.2094" velocity="1.0"/>
    <!-- Passive joint - follows control segment -->
    <mimic joint="seg1_joint_x" multiplier="1.0" offset="0.0"/>
    <dynamics damping="0.1" friction="0.0"/>
  </joint>
  <link name="seg2_x_link">
    <!-- No visual - invisible joint -->
    <inertial>
      <origin rpy="0 0 0" xyz="0 0 0"/>
      <mass value="0.01"/>
      <inertia ixx="0.00001" ixy="0" ixz="0" iyy="0.00001" iyz="0" izz="0.00001"/>
    </inertial>
  </link>
  <!-- Revolute Joint Y (Pitch) -->
  <joint name="seg2_joint_y" type="revolute">
    <parent link="seg2_x_link"/>
    <child link="seg2_y_link"/>
    <origin rpy="0 0 0" xyz="0 0 0"/>
    <axis xyz="0 1 0"/>
    <limit effort="100" lower="-0.2094" upper="0.2094" velocity="1.0"/>
    <!-- Passive joint - follows control segment -->
    <mimic joint="seg1_joint_y" multiplier="1.0" offset="0.0"/>
    <dynamics damping="0.1" friction="0.0"/>
  </joint>
  <link name="seg2_y_link">
    <!-- No visual - invisible joint -->
    <inertial>
      <origin rpy="0 0 0" xyz="0 0 0"/>
      <mass value="0.01"/>
      <inertia ixx="0.00001" ixy="0" ixz="0" iyy="0.00001" iyz="0" izz="0.00001"/>
    </inertial>
  </link>
  <!-- Fixed H distance joint -->
  <joint name="seg2_fixed_h" type="fixed">
    <parent link="seg2_y_link"/>
    <child link="seg2_mid_link"/>
    <origin rpy="0 0 0" xyz="0 0 0.022"/>
  </joint>
  <!-- Middle link with disc platform -->
  <link name="seg2_mid_link">
    <visual>
      <!-- Disc platform only -->
      <origin rpy="0 0 0" xyz="0 0 0"/>
      <geometry>
        <cylinder length="0.012" radius="0.0352"/>
      </geometry>
      <material name="disc_2">
        <color rgba="1.0 0.6 0.2 1.0"/>
      </material>
    </visual>
    <collision>
      <origin rpy="0 0 0" xyz="0 0 0"/>
      <geometry>
        <cylinder length="0.012" radius="0.0352"/>
      </geometry>
    </collision>
    <inertial>
      <origin rpy="0 0 0" xyz="0 0 0"/>
      <mass value="0.5"/>
      <inertia ixx="0.002" ixy="0" ixz="0" iyy="0.002" iyz="0" izz="0.003"/>
    </inertial>
  </link>
  <!-- Revolute Joint X (Roll) -->
  <joint name="seg3_joint_x" type="revolute">
    <parent link="seg2_mid_link"/>
    <child link="seg3_x_link"/>
    <origin rpy="0 0 0" xyz="0 0 0"/>
    <axis xyz="1 0 0"/>
    <limit effort="100" lower="-0.2094" upper="0.2094" velocity="1.0"/>
    <!-- Passive joint - follows control segment -->
    <mimic joint="seg1_joint_x" multiplier="1.0" offset="0.0"/>
    <dynamics damping="0.1" friction="0.0"/>
  </joint>
  <link name="seg3_x_link">
    <!-- No visual - invisible joint -->
    <inertial>
      <origin rpy="0 0 0" xyz="0 0 0"/>
      <mass value="0.01"/>
      <inertia ixx="0.00001" ixy="0" ixz="0" iyy="0.00001" iyz="0" izz="0.00001"/>
    </inertial>
  </link>
  <!-- Revolute Joint Y (Pitch) -->
  <joint name="seg3_joint_y" type="revolute">
    <parent link="seg3_x_link"/>
    <child link="seg3_y_link"/>
    <origin rpy="0 0 0" xyz="0 0 0"/>
    <axis xyz="0 1 0"/>
    <limit effort="100" lower="-0.2094" upper="0.2094" velocity="1.0"/>
    <!-- Passive joint - follows control segment -->
    <mimic joint="seg1_joint_y" multiplier="1.0" offset="0.0"/>
    <dynamics damping="0.1" friction="0.0"/>
  </joint>
  <link name="seg3_y_link">
    <!-- No visual - invisible joint -->
    <inertial>
      <origin rpy="0 0 0" xyz="0 0 0"/>
      <mass value="0.01"/>
      <inertia ixx="0.00001" ixy="0" ixz="0" iyy="0.00001" iyz="0" izz="0.00001"/>
    </inertial>
  </link>
  <!-- Fixed H distance joint -->
  <joint name="seg3_fixed_h" type="fixed">
    <parent link="seg3_y_link"/>
    <child link="seg3_mid_link"/>
    <origin rpy="0 0 0" xyz="0 0 0.022"/>
  </joint>
  <!-- Middle link with disc platform -->
  <link name="seg3_mid_link">
    <visual>
      <!-- Disc platform only -->
      <origin rpy="0 0 0" xyz="0 0 0"/>
      <geometry>
        <cylinder length="0.012" radius="0.0352"/>
      </geometry>
      <material name="disc_3">
        <color rgba="1.0 0.6 0.2 1.0"/>
      </material>
    </visual>
    <collision>
      <origin rpy="0 0 0" xyz="0 0 0"/>
      <geometry>
        <cylinder length="0.012" radius="0.0352"/>
      </geometry>
    </collision>
    <inertial>
      <origin rpy="0 0 0" xyz="0 0 0"/>
      <mass value="0.5"/>
      <inertia ixx="0.002" ixy="0" ixz="0" iyy="0.002" iyz="0" izz="0.003"/>
    </inertial>
  </link>
  <!-- Revolute Joint X (Roll) -->
  <joint name="seg4_joint_x" type="revolute">
    <parent link="seg3_mid_link"/>
    <child link="seg4_x_link"/>
    <origin rpy="0 0 0" xyz="0 0 0"/>
    <axis xyz="1 0 0"/>
    <limit effort="100" lower="-0.2094" upper="0.2094" velocity="1.0"/>
    <!-- Passive joint - follows control segment -->
    <mimic joint="seg1_joint_x" multiplier="1.0" offset="0.0"/>
    <dynamics damping="0.1" friction="0.0"/>
  </joint>
  <link name="seg4_x_link">
    <!-- No visual - invisible joint -->
    <inertial>
      <origin rpy="0 0 0" xyz="0 0 0"/>
      <mass value="0.01"/>
      <inertia ixx="0.00001" ixy="0" ixz="0" iyy="0.00001" iyz="0" izz="0.00001"/>
    </inertial>
  </link>
  <!-- Revolute Joint Y (Pitch) -->
  <joint name="seg4_joint_y" type="revolute">
    <parent link="seg4_x_link"/>
    <child link="seg4_y_link"/>
    <origin rpy="0 0 0" xyz="0 0 0"/>
    <axis xyz="0 1 0"/>
    <limit effort="100" lower="-0.2094" upper="0.2094" velocity="1.0"/>
    <!-- Passive joint - follows control segment -->
    <mimic joint="seg1_joint_y" multiplier="1.0" offset="0.0"/>
    <dynamics damping="0.1" friction="0.0"/>
  </joint>
  <link name="seg4_y_link">
    <!-- No visual - invisible joint -->
    <inertial>
      <origin rpy="0 0 0" xyz="0 0 0"/>
      <mass value="0.01"/>
      <inertia ixx="0.00001" ixy="0" ixz="0" iyy="0.00001" iyz="0" izz="0.00001"/>
    </inertial>
  </link>
  <!-- Fixed H distance joint -->
  <joint name="seg4_fixed_h" type="fixed">
    <parent link="seg4_y_link"/>
    <child link="seg4_mid_link"/>
    <origin rpy="0 0 0" xyz="0 0 0.022"/>
  </joint>
  <!-- Middle link with disc platform -->
  <link name="seg4_mid_link">
    <visual>
      <!-- Disc platform only -->
      <origin rpy="0 0 0" xyz="0 0 0"/>
      <geometry>
        <cylinder length="0.012" radius="0.0352"/>
      </geometry>
      <material name="disc_4">
        <color rgba="1.0 0.6 0.2 1.0"/>
      </material>
    </visual>
    <collision>
      <origin rpy="0 0 0" xyz="0 0 0"/>
      <geometry>
        <cylinder length="0.012" radius="0.0352"/>
      </geometry>
    </collision>
    <inertial>
      <origin rpy="0 0 0" xyz="0 0 0"/>
      <mass value="0.5"/>
      <inertia ixx="0.002" ixy="0" ixz="0" iyy="0.002" iyz="0" izz="0.003"/>
    </inertial>
  </link>
  <!-- Revolute Joint X (Roll) -->
  <joint name="seg5_joint_x" type="revolute">
    <parent link="seg4_mid_link"/>
    <child link="seg5_x_link"/>
    <origin rpy="0 0 0" xyz="0 0 0"/>
    <axis xyz="1 0 0"/>
    <limit effort="100" lower="-0.2094" upper="0.2094" velocity="1.0"/>
    <!-- Passive joint - follows control segment -->
    <mimic joint="seg1_joint_x" multiplier="1.0" offset="0.0"/>
    <dynamics damping="0.1" friction="0.0"/>
  </joint>
  <link name="seg5_x_link">
    <!-- No visual - invisible joint -->
    <inertial>
      <origin rpy="0 0 0" xyz="0 0 0"/>
      <mass value="0.01"/>
      <inertia ixx="0.00001" ixy="0" ixz="0" iyy="0.00001" iyz="0" izz="0.00001"/>
    </inertial>
  </link>
  <!-- Revolute Joint Y (Pitch) -->
  <joint name="seg5_joint_y" type="revolute">
    <parent link="seg5_x_link"/>
    <child link="seg5_y_link"/>
    <origin rpy="0 0 0" xyz="0 0 0"/>
    <axis xyz="0 1 0"/>
    <limit effort="100" lower="-0.2094" upper="0.2094" velocity="1.0"/>
    <!-- Passive joint - follows control segment -->
    <mimic joint="seg1_joint_y" multiplier="1.0" offset="0.0"/>
    <dynamics damping="0.1" friction="0.0"/>
  </joint>
  <link name="seg5_y_link">
    <!-- No visual - invisible joint -->
    <inertial>
      <origin rpy="0 0 0" xyz="0 0 0"/>
      <mass value="0.01"/>
      <inertia ixx="0.00001" ixy="0" ixz="0" iyy="0.00001" iyz="0" izz="0.00001"/>
    </inertial>
  </link>
  <!-- Fixed H distance joint -->
  <joint name="seg5_fixed_h" type="fixed">
    <parent link="seg5_y_link"/>
    <child link="seg5_mid_link"/>
    <origin rpy="0 0 0" xyz="0 0 0.022"/>
  </joint>
  <!-- Middle link with disc platform -->
  <link name="seg5_mid_link">
    <visual>
      <!-- Disc platform only -->
      <origin rpy="0 0 0" xyz="0 0 0"/>
      <geometry>
        <cylinder length="0.012" radius="0.0352"/>
      </geometry>
      <material name="disc_5">
        <color rgba="1.0 0.6 0.2 1.0"/>
      </material>
    </visual>
    <collision>
      <origin rpy="0 0 0" xyz="0 0 0"/>
      <geometry>
        <cylinder length="0.012" radius="0.0352"/>
      </geometry>
    </collision>
    <inertial>
      <origin rpy="0 0 0" xyz="0 0 0"/>
      <mass value="0.5"/>
      <inertia ixx="0.002" ixy="0" ixz="0" iyy="0.002" iyz="0" izz="0.003"/>
    </inertial>
  </link>
  <!-- Revolute Joint X (Roll) -->
  <joint name="seg6_joint_x" type="revolute">
    <parent link="seg5_mid_link"/>
    <child link="seg6_x_link"/>
    <origin rpy="0 0 0" xyz="0 0 0"/>
    <axis xyz="1 0 0"/>
    <limit effort="100" lower="-0.2094" upper="0.2094" velocity="1.0"/>
    <!-- Passive joint - follows control segment -->
    <mimic joint="seg1_joint_x" multiplier="1.0" offset="0.0"/>
    <dynamics damping="0.1" friction="0.0"/>
  </joint>
  <link name="seg6_x_link">
    <!-- No visual - invisible joint -->
    <inertial>
      <origin rpy="0 0 0" xyz="0 0 0"/>
      <mass value="0.01"/>
      <inertia ixx="0.00001" ixy="0" ixz="0" iyy="0.00001" iyz="0" izz="0.00001"/>
    </inertial>
  </link>
  <!-- Revolute Joint Y (Pitch) -->
  <joint name="seg6_joint_y" type="revolute">
    <parent link="seg6_x_link"/>
    <child link="seg6_y_link"/>
    <origin rpy="0 0 0" xyz="0 0 0"/>
    <axis xyz="0 1 0"/>
    <limit effort="100" lower="-0.2094" upper="0.2094" velocity="1.0"/>
    <!-- Passive joint - follows control segment -->
    <mimic joint="seg1_joint_y" multiplier="1.0" offset="0.0"/>
    <dynamics damping="0.1" friction="0.0"/>
  </joint>
  <link name="seg6_y_link">
    <!-- No visual - invisible joint -->
    <inertial>
      <origin rpy="0 0 0" xyz="0 0 0"/>
      <mass value="0.01"/>
      <inertia ixx="0.00001" ixy="0" ixz="0" iyy="0.00001" iyz="0" izz="0.00001"/>
    </inertial>
  </link>
  <!-- Fixed H distance joint -->
  <joint name="seg6_fixed_h" type="fixed">
    <parent link="seg6_y_link"/>
    <child link="seg6_mid_link"/>
    <origin rpy="0 0 0" xyz="0 0 0.022"/>
  </joint>
  <!-- Middle link with disc platform -->
  <link name="seg6_mid_link">
    <visual>
      <!-- Disc platform only -->
      <origin rpy="0 0 0" xyz="0 0 0"/>
      <geometry>
        <cylinder length="0.012" radius="0.0352"/>
      </geometry>
      <material name="disc_6">
        <color rgba="1.0 0.6 0.2 1.0"/>
      </material>
    </visual>
    <collision>
      <origin rpy="0 0 0" xyz="0 0 0"/>
      <geometry>
        <cylinder length="0.012" radius="0.0352"/>
      </geometry>
    </collision>
    <inertial>
      <origin rpy="0 0 0" xyz="0 0 0"/>
      <mass value="0.5"/>
      <inertia ixx="0.002" ixy="0" ixz="0" iyy="0.002" iyz="0" izz="0.003"/>
    </inertial>
  </link>
  <!-- Revolute Joint X (Roll) -->
  <joint name="seg7_joint_x" type="revolute">
    <parent link="seg6_mid_link"/>
    <child link="seg7_x_link"/>
    <origin rpy="0 0 0" xyz="0 0 0"/>
    <axis xyz="1 0 0"/>
    <limit effort="100" lower="-0.2094" upper="0.2094" velocity="1.0"/>
    <!-- Passive joint - follows control segment -->
    <mimic joint="seg1_joint_x" multiplier="1.0" offset="0.0"/>
    <dynamics damping="0.1" friction="0.0"/>
  </joint>
  <link name="seg7_x_link">
    <!-- No visual - invisible joint -->
    <inertial>
      <origin rpy="0 0 0" xyz="0 0 0"/>
      <mass value="0.01"/>
      <inertia ixx="0.00001" ixy="0" ixz="0" iyy="0.00001" iyz="0" izz="0.00001"/>
    </inertial>
  </link>
  <!-- Revolute Joint Y (Pitch) -->
  <joint name="seg7_joint_y" type="revolute">
    <parent link="seg7_x_link"/>
    <child link="seg7_y_link"/>
    <origin rpy="0 0 0" xyz="0 0 0"/>
    <axis xyz="0 1 0"/>
    <limit effort="100" lower="-0.2094" upper="0.2094" velocity="1.0"/>
    <!-- Passive joint - follows control segment -->
    <mimic joint="seg1_joint_y" multiplier="1.0" offset="0.0"/>
    <dynamics damping="0.1" friction="0.0"/>
  </joint>
  <link name="seg7_y_link">
    <!-- No visual - invisible joint -->
    <inertial>
      <origin rpy="0 0 0" xyz="0 0 0"/>
      <mass value="0.01"/>
      <inertia ixx="0.00001" ixy="0" ixz="0" iyy="0.00001" iyz="0" izz="0.00001"/>
    </inertial>
  </link>
  <!-- Fixed H distance joint -->
  <joint name="seg7_fixed_h" type="fixed">
    <parent link="seg7_y_link"/>
    <child link="seg7_mid_link"/>
    <origin rpy="0 0 0" xyz="0 0 0.022"/>
  </joint>
  <!-- Middle link with disc platform -->
  <link name="seg7_mid_link">
    <visual>
      <!-- Disc platform only -->
      <origin rpy="0 0 0" xyz="0 0 0"/>
      <geometry>
        <cylinder length="0.012" radius="0.0352"/>
      </geometry>
      <material name="disc_7">
        <color rgba="1.0 0.6 0.2 1.0"/>
      </material>
    </visual>
    <collision>
      <origin rpy="0 0 0" xyz="0 0 0"/>
      <geometry>
        <cylinder length="0.012" radius="0.0352"/>
      </geometry>
    </collision>
    <inertial>
      <origin rpy="0 0 0" xyz="0 0 0"/>
      <mass value="0.5"/>
      <inertia ixx="0.002" ixy="0" ixz="0" iyy="0.002" iyz="0" izz="0.003"/>
    </inertial>
  </link>
  <!-- ===== TOP HALF: 7 segments controlled by seg8 (CYAN) ===== -->
  <!-- Revolute Joint X (Roll) -->
  <joint name="seg8_joint_x" type="revolute">
    <parent link="seg7_mid_link"/>
    <child link="seg8_x_link"/>
    <origin rpy="0 0 0" xyz="0 0 0"/>
    <axis xyz="1 0 0"/>
    <limit effort="100" lower="-0.2094" upper="0.2094" velocity="1.0"/>
    <dynamics damping="0.7" friction="0.0"/>
  </joint>
  <link name="seg8_x_link">
    <!-- No visual - invisible joint -->
    <inertial>
      <origin rpy="0 0 0" xyz="0 0 0"/>
      <mass value="0.01"/>
      <inertia ixx="0.00001" ixy="0" ixz="0" iyy="0.00001" iyz="0" izz="0.00001"/>
    </inertial>
  </link>
  <!-- Revolute Joint Y (Pitch) -->
  <joint name="seg8_joint_y" type="revolute">
    <parent link="seg8_x_link"/>
    <child link="seg8_y_link"/>
    <origin rpy="0 0 0" xyz="0 0 0"/>
    <axis xyz="0 1 0"/>
    <limit effort="100" lower="-0.2094" upper="0.2094" velocity="1.0"/>
    <dynamics damping="0.7" friction="0.0"/>
  </joint>
  <link name="seg8_y_link">
    <!-- No visual - invisible joint -->
    <inertial>
      <origin rpy="0 0 0" xyz="0 0 0"/>
      <mass value="0.01"/>
      <inertia ixx="0.00001" ixy="0" ixz="0" iyy="0.00001" iyz="0" izz="0.00001"/>
    </inertial>
  </link>
  <!-- Fixed H distance joint -->
  <joint name="seg8_fixed_h" type="fixed">
    <parent link="seg8_y_link"/>
    <child link="seg8_mid_link"/>
    <origin rpy="0 0 0" xyz="0 0 0.022"/>
  </joint>
  <!-- Middle link with disc platform -->
  <link name="seg8_mid_link">
    <visual>
      <!-- Disc platform only -->
      <origin rpy="0 0 0" xyz="0 0 0"/>
      <geometry>
        <cylinder length="0.012" radius="0.0352"/>
      </geometry>
      <material name="disc_8">
        <color rgba="0.2 0.8 0.9 1.0"/>
      </material>
    </visual>
    <collision>
      <origin rpy="0 0 0" xyz="0 0 0"/>
      <geometry>
        <cylinder length="0.012" radius="0.0352"/>
      </geometry>
    </collision>
    <inertial>
      <origin rpy="0 0 0" xyz="0 0 0"/>
      <mass value="0.5"/>
      <inertia ixx="0.002" ixy="0" ixz="0" iyy="0.002" iyz="0" izz="0.003"/>
    </inertial>
  </link>
  <!-- Revolute Joint X (Roll) -->
  <joint name="seg9_joint_x" type="revolute">
    <parent link="seg8_mid_link"/>
    <child link="seg9_x_link"/>
    <origin rpy="0 0 0" xyz="0 0 0"/>
    <axis xyz="1 0 0"/>
    <limit effort="100" lower="-0.2094" upper="0.2094" velocity="1.0"/>
    <!-- Passive joint - follows control segment -->
    <mimic joint="seg8_joint_x" multiplier="1.0" offset="0.0"/>
    <dynamics damping="0.1" friction="0.0"/>
  </joint>
  <link name="seg9_x_link">
    <!-- No visual - invisible joint -->
    <inertial>
      <origin rpy="0 0 0" xyz="0 0 0"/>
      <mass value="0.01"/>
      <inertia ixx="0.00001" ixy="0" ixz="0" iyy="0.00001" iyz="0" izz="0.00001"/>
    </inertial>
  </link>
  <!-- Revolute Joint Y (Pitch) -->
  <joint name="seg9_joint_y" type="revolute">
    <parent link="seg9_x_link"/>
    <child link="seg9_y_link"/>
    <origin rpy="0 0 0" xyz="0 0 0"/>
    <axis xyz="0 1 0"/>
    <limit effort="100" lower="-0.2094" upper="0.2094" velocity="1.0"/>
    <!-- Passive joint - follows control segment -->
    <mimic joint="seg8_joint_y" multiplier="1.0" offset="0.0"/>
    <dynamics damping="0.1" friction="0.0"/>
  </joint>
  <link name="seg9_y_link">
    <!-- No visual - invisible joint -->
    <inertial>
      <origin rpy="0 0 0" xyz="0 0 0"/>
      <mass value="0.01"/>
      <inertia ixx="0.00001" ixy="0" ixz="0" iyy="0.00001" iyz="0" izz="0.00001"/>
    </inertial>
  </link>
  <!-- Fixed H distance joint -->
  <joint name="seg9_fixed_h" type="fixed">
    <parent link="seg9_y_link"/>
    <child link="seg9_mid_link"/>
    <origin rpy="0 0 0" xyz="0 0 0.022"/>
  </joint>
  <!-- Middle link with disc platform -->
  <link name="seg9_mid_link">
    <visual>
      <!-- Disc platform only -->
      <origin rpy="0 0 0" xyz="0 0 0"/>
      <geometry>
        <cylinder length="0.012" radius="0.0352"/>
      </geometry>
      <material name="disc_9">
        <color rgba="0.2 0.8 0.9 1.0"/>
      </material>
    </visual>
    <collision>
      <origin rpy="0 0 0" xyz="0 0 0"/>
      <geometry>
        <cylinder length="0.012" radius="0.0352"/>
      </geometry>
    </collision>
    <inertial>
      <origin rpy="0 0 0" xyz="0 0 0"/>
      <mass value="0.5"/>
      <inertia ixx="0.002" ixy="0" ixz="0" iyy="0.002" iyz="0" izz="0.003"/>
    </inertial>
  </link>
  <!-- Revolute Joint X (Roll) -->
  <joint name="seg10_joint_x" type="revolute">
    <parent link="seg9_mid_link"/>
    <child link="seg10_x_link"/>
    <origin rpy="0 0 0" xyz="0 0 0"/>
    <axis xyz="1 0 0"/>
    <limit effort="100" lower="-0.2094" upper="0.2094" velocity="1.0"/>
    <!-- Passive joint - follows control segment -->
    <mimic joint="seg8_joint_x" multiplier="1.0" offset="0.0"/>
    <dynamics damping="0.1" friction="0.0"/>
  </joint>
  <link name="seg10_x_link">
    <!-- No visual - invisible joint -->
    <inertial>
      <origin rpy="0 0 0" xyz="0 0 0"/>
      <mass value="0.01"/>
      <inertia ixx="0.00001" ixy="0" ixz="0" iyy="0.00001" iyz="0" izz="0.00001"/>
    </inertial>
  </link>
  <!-- Revolute Joint Y (Pitch) -->
  <joint name="seg10_joint_y" type="revolute">
    <parent link="seg10_x_link"/>
    <child link="seg10_y_link"/>
    <origin rpy="0 0 0" xyz="0 0 0"/>
    <axis xyz="0 1 0"/>
    <limit effort="100" lower="-0.2094" upper="0.2094" velocity="1.0"/>
    <!-- Passive joint - follows control segment -->
    <mimic joint="seg8_joint_y" multiplier="1.0" offset="0.0"/>
    <dynamics damping="0.1" friction="0.0"/>
  </joint>
  <link name="seg10_y_link">
    <!-- No visual - invisible joint -->
    <inertial>
      <origin rpy="0 0 0" xyz="0 0 0"/>
      <mass value="0.01"/>
      <inertia ixx="0.00001" ixy="0" ixz="0" iyy="0.00001" iyz="0" izz="0.00001"/>
    </inertial>
  </link>
  <!-- Fixed H distance joint -->
  <joint name="seg10_fixed_h" type="fixed">
    <parent link="seg10_y_link"/>
    <child link="seg10_mid_link"/>
    <origin rpy="0 0 0" xyz="0 0 0.022"/>
  </joint>
  <!-- Middle link with disc platform -->
  <link name="seg10_mid_link">
    <visual>
      <!-- Disc platform only -->
      <origin rpy="0 0 0" xyz="0 0 0"/>
      <geometry>
        <cylinder length="0.012" radius="0.0352"/>
      </geometry>
      <material name="disc_10">
        <color rgba="0.2 0.8 0.9 1.0"/>
      </material>
    </visual>
    <collision>
      <origin rpy="0 0 0" xyz="0 0 0"/>
      <geometry>
        <cylinder length="0.012" radius="0.0352"/>
      </geometry>
    </collision>
    <inertial>
      <origin rpy="0 0 0" xyz="0 0 0"/>
      <mass value="0.5"/>
      <inertia ixx="0.002" ixy="0" ixz="0" iyy="0.002" iyz="0" izz="0.003"/>
    </inertial>
  </link>
  <!-- Revolute Joint X (Roll) -->
  <joint name="seg11_joint_x" type="revolute">
    <parent link="seg10_mid_link"/>
    <child link="seg11_x_link"/>
    <origin rpy="0 0 0" xyz="0 0 0"/>
    <axis xyz="1 0 0"/>
    <limit effort="100" lower="-0.2094" upper="0.2094" velocity="1.0"/>
    <!-- Passive joint - follows control segment -->
    <mimic joint="seg8_joint_x" multiplier="1.0" offset="0.0"/>
    <dynamics damping="0.1" friction="0.0"/>
  </joint>
  <link name="seg11_x_link">
    <!-- No visual - invisible joint -->
    <inertial>
      <origin rpy="0 0 0" xyz="0 0 0"/>
      <mass value="0.01"/>
      <inertia ixx="0.00001" ixy="0" ixz="0" iyy="0.00001" iyz="0" izz="0.00001"/>
    </inertial>
  </link>
  <!-- Revolute Joint Y (Pitch) -->
  <joint name="seg11_joint_y" type="revolute">
    <parent link="seg11_x_link"/>
    <child link="seg11_y_link"/>
    <origin rpy="0 0 0" xyz="0 0 0"/>
    <axis xyz="0 1 0"/>
    <limit effort="100" lower="-0.2094" upper="0.2094" velocity="1.0"/>
    <!-- Passive joint - follows control segment -->
    <mimic joint="seg8_joint_y" multiplier="1.0" offset="0.0"/>
    <dynamics damping="0.1" friction="0.0"/>
  </joint>
  <link name="seg11_y_link">
    <!-- No visual - invisible joint -->
    <inertial>
      <origin rpy="0 0 0" xyz="0 0 0"/>
      <mass value="0.01"/>
      <inertia ixx="0.00001" ixy="0" ixz="0" iyy="0.00001" iyz="0" izz="0.00001"/>
    </inertial>
  </link>
  <!-- Fixed H distance joint -->
  <joint name="seg11_fixed_h" type="fixed">
    <parent link="seg11_y_link"/>
    <child link="seg11_mid_link"/>
    <origin rpy="0 0 0" xyz="0 0 0.022"/>
  </joint>
  <!-- Middle link with disc platform -->
  <link name="seg11_mid_link">
    <visual>
      <!-- Disc platform only -->
      <origin rpy="0 0 0" xyz="0 0 0"/>
      <geometry>
        <cylinder length="0.012" radius="0.0352"/>
      </geometry>
      <material name="disc_11">
        <color rgba="0.2 0.8 0.9 1.0"/>
      </material>
    </visual>
    <collision>
      <origin rpy="0 0 0" xyz="0 0 0"/>
      <geometry>
        <cylinder length="0.012" radius="0.0352"/>
      </geometry>
    </collision>
    <inertial>
      <origin rpy="0 0 0" xyz="0 0 0"/>
      <mass value="0.5"/>
      <inertia ixx="0.002" ixy="0" ixz="0" iyy="0.002" iyz="0" izz="0.003"/>
    </inertial>
  </link>
  <!-- Revolute Joint X (Roll) -->
  <joint name="seg12_joint_x" type="revolute">
    <parent link="seg11_mid_link"/>
    <child link="seg12_x_link"/>
    <origin rpy="0 0 0" xyz="0 0 0"/>
    <axis xyz="1 0 0"/>
    <limit effort="100" lower="-0.2094" upper="0.2094" velocity="1.0"/>
    <!-- Passive joint - follows control segment -->
    <mimic joint="seg8_joint_x" multiplier="1.0" offset="0.0"/>
    <dynamics damping="0.1" friction="0.0"/>
  </joint>
  <link name="seg12_x_link">
    <!-- No visual - invisible joint -->
    <inertial>
      <origin rpy="0 0 0" xyz="0 0 0"/>
      <mass value="0.01"/>
      <inertia ixx="0.00001" ixy="0" ixz="0" iyy="0.00001" iyz="0" izz="0.00001"/>
    </inertial>
  </link>
  <!-- Revolute Joint Y (Pitch) -->
  <joint name="seg12_joint_y" type="revolute">
    <parent link="seg12_x_link"/>
    <child link="seg12_y_link"/>
    <origin rpy="0 0 0" xyz="0 0 0"/>
    <axis xyz="0 1 0"/>
    <limit effort="100" lower="-0.2094" upper="0.2094" velocity="1.0"/>
    <!-- Passive joint - follows control segment -->
    <mimic joint="seg8_joint_y" multiplier="1.0" offset="0.0"/>
    <dynamics damping="0.1" friction="0.0"/>
  </joint>
  <link name="seg12_y_link">
    <!-- No visual - invisible joint -->
    <inertial>
      <origin rpy="0 0 0" xyz="0 0 0"/>
      <mass value="0.01"/>
      <inertia ixx="0.00001" ixy="0" ixz="0" iyy="0.00001" iyz="0" izz="0.00001"/>
    </inertial>
  </link>
  <!-- Fixed H distance joint -->
  <joint name="seg12_fixed_h" type="fixed">
    <parent link="seg12_y_link"/>
    <child link="seg12_mid_link"/>
    <origin rpy="0 0 0" xyz="0 0 0.022"/>
  </joint>
  <!-- Middle link with disc platform -->
  <link name="seg12_mid_link">
    <visual>
      <!-- Disc platform only -->
      <origin rpy="0 0 0" xyz="0 0 0"/>
      <geometry>
        <cylinder length="0.012" radius="0.0352"/>
      </geometry>
      <material name="disc_12">
        <color rgba="0.2 0.8 0.9 1.0"/>
      </material>
    </visual>
    <collision>
      <origin rpy="0 0 0" xyz="0 0 0"/>
      <geometry>
        <cylinder length="0.012" radius="0.0352"/>
      </geometry>
    </collision>
    <inertial>
      <origin rpy="0 0 0" xyz="0 0 0"/>
      <mass value="0.5"/>
      <inertia ixx="0.002" ixy="0" ixz="0" iyy="0.002" iyz="0" izz="0.003"/>
    </inertial>
  </link>
  <!-- Revolute Joint X (Roll) -->
  <joint name="seg13_joint_x" type="revolute">
    <parent link="seg12_mid_link"/>
    <child link="seg13_x_link"/>
    <origin rpy="0 0 0" xyz="0 0 0"/>
    <axis xyz="1 0 0"/>
    <limit effort="100" lower="-0.2094" upper="0.2094" velocity="1.0"/>
    <!-- Passive joint - follows control segment -->
    <mimic joint="seg8_joint_x" multiplier="1.0" offset="0.0"/>
    <dynamics damping="0.1" friction="0.0"/>
  </joint>
  <link name="seg13_x_link">
    <!-- No visual - invisible joint -->
    <inertial>
      <origin rpy="0 0 0" xyz="0 0 0"/>
      <mass value="0.01"/>
      <inertia ixx="0.00001" ixy="0" ixz="0" iyy="0.00001" iyz="0" izz="0.00001"/>
    </inertial>
  </link>
  <!-- Revolute Joint Y (Pitch) -->
  <joint name="seg13_joint_y" type="revolute">
    <parent link="seg13_x_link"/>
    <child link="seg13_y_link"/>
    <origin rpy="0 0 0" xyz="0 0 0"/>
    <axis xyz="0 1 0"/>
    <limit effort="100" lower="-0.2094" upper="0.2094" velocity="1.0"/>
    <!-- Passive joint - follows control segment -->
    <mimic joint="seg8_joint_y" multiplier="1.0" offset="0.0"/>
    <dynamics damping="0.1" friction="0.0"/>
  </joint>
  <link name="seg13_y_link">
    <!-- No visual - invisible joint -->
    <inertial>
      <origin rpy="0 0 0" xyz="0 0 0"/>
      <mass value="0.01"/>
      <inertia ixx="0.00001" ixy="0" ixz="0" iyy="0.00001" iyz="0" izz="0.00001"/>
    </inertial>
  </link>
  <!-- Fixed H distance joint -->
  <joint name="seg13_fixed_h" type="fixed">
    <parent link="seg13_y_link"/>
    <child link="seg13_mid_link"/>
    <origin rpy="0 0 0" xyz="0 0 0.022"/>
  </joint>
  <!-- Middle link with disc platform -->
  <link name="seg13_mid_link">
    <visual>
      <!-- Disc platform only -->
      <origin rpy="0 0 0" xyz="0 0 0"/>
      <geometry>
        <cylinder length="0.012" radius="0.0352"/>
      </geometry>
      <material name="disc_13">
        <color rgba="0.2 0.8 0.9 1.0"/>
      </material>
    </visual>
    <collision>
      <origin rpy="0 0 0" xyz="0 0 0"/>
      <geometry>
        <cylinder length="0.012" radius="0.0352"/>
      </geometry>
    </collision>
    <inertial>
      <origin rpy="0 0 0" xyz="0 0 0"/>
      <mass value="0.5"/>
      <inertia ixx="0.002" ixy="0" ixz="0" iyy="0.002" iyz="0" izz="0.003"/>
    </inertial>
  </link>
  <!-- Revolute Joint X (Roll) -->
  <joint name="seg14_joint_x" type="revolute">
    <parent link="seg13_mid_link"/>
    <child link="seg14_x_link"/>
    <origin rpy="0 0 0" xyz="0 0 0"/>
    <axis xyz="1 0 0"/>
    <limit effort="100" lower="-0.2094" upper="0.2094" velocity="1.0"/>
    <!-- Passive joint - follows control segment -->
    <mimic joint="seg8_joint_x" multiplier="1.0" offset="0.0"/>
    <dynamics damping="0.1" friction="0.0"/>
  </joint>
  <link name="seg14_x_link">
    <!-- No visual - invisible joint -->
    <inertial>
      <origin rpy="0 0 0" xyz="0 0 0"/>
      <mass value="0.01"/>
      <inertia ixx="0.00001" ixy="0" ixz="0" iyy="0.00001" iyz="0" izz="0.00001"/>
    </inertial>
  </link>
  <!-- Revolute Joint Y (Pitch) -->
  <joint name="seg14_joint_y" type="revolute">
    <parent link="seg14_x_link"/>
    <child link="seg14_y_link"/>
    <origin rpy="0 0 0" xyz="0 0 0"/>
    <axis xyz="0 1 0"/>
    <limit effort="100" lower="-0.2094" upper="0.2094" velocity="1.0"/>
    <!-- Passive joint - follows control segment -->
    <mimic joint="seg8_joint_y" multiplier="1.0" offset="0.0"/>
    <dynamics damping="0.1" friction="0.0"/>
  </joint>
  <link name="seg14_y_link">
    <!-- No visual - invisible joint -->
    <inertial>
      <origin rpy="0 0 0" xyz="0 0 0"/>
      <mass value="0.01"/>
      <inertia ixx="0.00001" ixy="0" ixz="0" iyy="0.00001" iyz="0" izz="0.00001"/>
    </inertial>
  </link>
  <!-- Fixed H distance joint -->
  <joint name="seg14_fixed_h" type="fixed">
    <parent link="seg14_y_link"/>
    <child link="seg14_mid_link"/>
    <origin rpy="0 0 0" xyz="0 0 0.022"/>
  </joint>
  <!-- Middle link with disc platform -->
  <link name="seg14_mid_link">
    <visual>
      <!-- Disc platform only -->
      <origin rpy="0 0 0" xyz="0 0 0"/>
      <geometry>
        <cylinder length="0.012" radius="0.0352"/>
      </geometry>
      <material name="disc_14">
        <color rgba="0.2 0.8 0.9 1.0"/>
      </material>
    </visual>
    <collision>
      <origin rpy="0 0 0" xyz="0 0 0"/>
      <geometry>
        <cylinder length="0.012" radius="0.0352"/>
      </geometry>
    </collision>
    <inertial>
      <origin rpy="0 0 0" xyz="0 0 0"/>
      <mass value="0.5"/>
      <inertia ixx="0.002" ixy="0" ixz="0" iyy="0.002" iyz="0" izz="0.003"/>
    </inertial>
  </link>
  <!-- End Effector -->
  <joint name="ee_joint" type="fixed">
    <parent link="seg14_mid_link"/>
    <child link="end_effector"/>
    <origin rpy="0 0 0" xyz="0 0 0.006"/>
  </joint>
  <link name="end_effector">
    <visual>
      <origin rpy="0 0 0" xyz="0 0 0.02"/>
      <geometry>
        <sphere radius="0.025"/>
      </geometry>
      <material name="green">
        <color rgba="0.2 0.9 0.2 1.0"/>
      </material>
    </visual>
    <inertial>
      <mass value="0.01"/>
      <inertia ixx="0.00001" ixy="0" ixz="0" iyy="0.00001" iyz="0" izz="0.00001"/>
    </inertial>
  </link>
</robot>
